Workbook

Sheet 操作处罚记录
A1: 文本序 | B1: 股票代码 | C1: 股票名称 | D1: 开始日期 | E1: 结束日期 | F1: 操纵期间 | G1: 处罚宣告日 | H1: 备注
A2: 202423 | B2: =VLOOKUP(C2,'全部股票代码（手动检索）'!A:B,2,0) -> 002730.SZ | C2: 电光科技 | D2: 44180 | E2: 44517 | G2: 45352
A3: 202409 | B3: =VLOOKUP(C3,'全部股票代码（手动检索）'!A:B,2,0) -> F1007420.00 | C3: 美尚生态 | D3: 43263 | E3: 44015 | G3: 45307
A4: 202406 | C4: “维格娜丝”等11支股票 | G4: 45306
B5: =VLOOKUP(C5,补充空白与2019的股票代码!A:B,2,0) -> 603518.SH | C5: 维格娜丝 | D5: 42941 | E5: 42961 | F5: 2017年7月25日至8月14日 | H5: 1支股票在两段时期内被操纵
B6: =VLOOKUP(C6,补充空白与2019的股票代码!A:B,2,0) -> 603518.SH | C6: 维格娜丝 | D6: 42970 | E6: 42992 | F6: 2017年8月23日至9月14日
B7: =VLOOKUP(C7,补充空白与2019的股票代码!A:B,2,0) -> 603665.SH | C7: 康隆达 | D7: 42998 | E7: 43007 | F7: 2017年9月20日至9月29日
B8: =VLOOKUP(C8,补充空白与2019的股票代码!A:B,2,0) -> 603586.SH | C8: 金麒麟 | D8: 42969 | E8: 42978 | F8: 2017年8月22日至8月31日 | H8: 1支股票在两段时期内被操纵
B9: =VLOOKUP(C9,补充空白与2019的股票代码!A:B,2,0) -> 603586.SH | C9: 金麒麟 | D9: 42982 | E9: 43000 | F9: 2017年9月4日至9月22日
B10: =VLOOKUP(C10,补充空白与2019的股票代码!A:B,2,0) -> 603926.SH | C10: 铁流股份 | D10: 42962 | E10: 42972 | F10: 2017年8月15日至8月25日
B11: =VLOOKUP(C11,补充空白与2019的股票代码!A:B,2,0) -> 603116.SH | C11: 红蜻蜓 | D11: 42940 | E11: 42949 | F11: 2017年7月24日至8月2日 | H11: 1支股票在两段时期内被操纵
B12: =VLOOKUP(C12,补充空白与2019的股票代码!A:B,2,0) -> 603116.SH | C12: 红蜻蜓 | D12: 42978 | E12: 42986 | F12: 2017年8月31日至9月8日
B13: =VLOOKUP(C13,补充空白与2019的股票代码!A:B,2,0) -> 603218.SH | C13: 日月股份 | D13: 42936 | E13: 42942 | F13: 2017年7月20日至7月26日
B14: =VLOOKUP(C14,补充空白与2019的股票代码!A:B,2,0) -> 603877.SH | C14: 太平鸟 | D14: 42912 | E14: 42923 | F14: 2017年6月26日至7月7日 | H14: 1支股票在两段时期内被操纵
B15: =VLOOKUP(C15,补充空白与2019的股票代码!A:B,2,0) -> 603877.SH | C15: 太平鸟 | D15: 42936 | E15: 42944 | F15: 2017年7月20日至7月28日
B16: =VLOOKUP(C16,补充空白与2019的股票代码!A:B,2,0) -> 603758.SH | C16: 秦安股份 | D16: 43172 | E16: 43193 | F16: 2018年3月13日至4月3日
B17: =VLOOKUP(C17,补充空白与2019的股票代码!A:B,2,0) -> 603159.SH | C17: 上海亚虹 | D17: 43168 | E17: 43175 | F17: 2018年3月9日至3月16日
B18: =VLOOKUP(C18,补充空白与2019的股票代码!A:B,2,0) -> 603985.SH | C18: 恒润股份 | D18: 43192 | E18: 43215 | F18: 2018年4月2日至4月25日
B19: =VLOOKUP(C19,补充空白与2019的股票代码!A:B,2,0) -> 603767.SH | C19: 中马传动 | D19: 43165 | E19: 43201 | F19: 2018年3月6日至4月11日
A20: 202402 | B20: =VLOOKUP(C20,'全部股票代码（手动检索）'!A:B,2,0) -> 300289.SZ | C20: 利德曼 | D20: 42801 | E20: 42951 | G20: 45296
A21: 2023151 | B21: =VLOOKUP(C21,'全部股票代码（手动检索）'!A:B,2,0) -> 603638.SH | C21: 艾迪精密 | D21: 43228 | E21: 44761 | G21: 45279
A22: 202383 | C22: 劲拓股份 | D22: 43045 | E22: 43584 | F22: 2017年11月6日至2019年4月29日 | G22: 45260
A23: 202377 | B23: =VLOOKUP(C23,'全部股票代码（手动检索）'!A:B,2,0) -> 002358.SZ | C23: 森源电气 | D23: 43166 | E23: 43523 | G23: 45230 | H23: 操纵行为分成三个阶段，开始日期与结束日期分别为操作行为最早开始时间和最晚结束时间
A24: 202371 | B24: =VLOOKUP(C24,'全部股票代码（手动检索）'!A:B,2,0) -> 300503.SZ | C24: 昊志机电 | D24: 44554 | E24: 44558 | G24: 45224 | H24: 内幕交易
A25: 202370 | B25: =VLOOKUP(C25,'全部股票代码（手动检索）'!A:B,2,0) -> F1002802.00 | C25: 金一文化 | D25: 43076 | E25: 43248 | F25: 2017年12月7日至2018年5月28日 | G25: 45222
A26: 202368 | C26: “利民股份”等16只股票 | G26: 45191 | H26: 操纵多支股票
B27: =VLOOKUP(C27,'全部股票代码（手动检索）'!A:B,2,0) -> 002734.SZ | C27: 利民股份 | D27: 42345 | E27: 42489 | F27: 2015年12月7日至2016年4月29日
B28: =VLOOKUP(C28,'全部股票代码（手动检索）'!A:B,2,0) -> 600328.SH | C28: 兰太实业 | D28: 42314 | E28: 42479 | F28: 2015年11月6日至2016年4月19日
B29: =VLOOKUP(C29,'全部股票代码（手动检索）'!A:B,2,0) -> 603309.SH | C29: 维力医疗 | D29: 42341 | E29: 42489 | F29: 2015年12月3日至2016年4月29日
B30: =VLOOKUP(C30,'全部股票代码（手动检索）'!A:B,2,0) -> 600560.SH | C30: 金自天正 | D30: 42332 | E30: 42537 | F30: 2015年11月24日至2016年6月16日
B31: =VLOOKUP(C31,'全部股票代码（手动检索）'!A:B,2,0) -> 600310.SH | C31: 桂东电力 | D31: 42384 | E31: 42480 | F31: 2016年1月15日至4月20日
B32: =VLOOKUP(C32,'全部股票代码（手动检索）'!A:B,2,0) -> 300309.SZ | C32: 吉艾科技 | D32: 42318 | E32: 42522 | F32: 2015年11月10日至2016年6月1日
B33: =VLOOKUP(C33,'全部股票代码（手动检索）'!A:B,2,0) -> 000411.SZ | C33: 英特集团 | D33: 42396 | E33: 42544 | F33: 2016年1月27日至2016年6月23日
B34: =VLOOKUP(C34,'全部股票代码（手动检索）'!A:B,2,0) -> 000702.SZ | C34: 正虹科技 | D34: 42180 | E34: 42562 | F34: 2015年6月25日至2016年7月11日
B35: =VLOOKUP(C35,'全部股票代码（手动检索）'!A:B,2,0) -> 000691.SZ | C35: 亚太实业 | D35: 42236 | E35: 42325 | F35: 2015年8月20日至11月17日
B36: =VLOOKUP(C36,'全部股票代码（手动检索）'!A:B,2,0) -> 300478.SZ | C36: 杭州高新 | D36: 42212 | E36: 42332 | F36: 2015年7月27日至11月24日
B37: =VLOOKUP(C37,'全部股票代码（手动检索）'!A:B,2,0) -> 002072.SZ | C37: 凯瑞德 | D37: 42396 | E37: 42710 | F37: 2016年1月27日至12月6日
B38: =VLOOKUP(C38,'全部股票代码（手动检索）'!A:B,2,0) -> 002509.SZ | C38: 天广消防 | D38: 42227 | E38: 42440 | F38: 2015年8月11日至2016年3月11日
... B42: =VLOOKUP(C42,'全部股票代码（手动检索）'!A:B,2,0) -> 600165.SH | C42: 新日恒力 | D42: 42759 | E42: 42822 | F42: 2017年1月24日至3月28日
A43: 202364 | B43: =VLOOKUP(C43,'全部股票代码（手动检索）'!A:B,2,0) -> 832966.NQ | C43: 道尔智控 | D43: 42984 | E43: 43112 | F43: 2017年9月6日至2018年1月12日 | G43: 45170
...

Sheet 全部股票代码（手动检索）
A1: 股票名称
A2: 电光科技 | B2: =VLOOKUP(A2,部分股票代码!A:B,2,0) -> 002730.SZ
A3: 美尚生态 | B3: F1007420.00
A4: 利德曼 | B4: =VLOOKUP(A4,部分股票代码!A:B,2,0) -> 300289.SZ
A5: 艾迪精密 | B5: =VLOOKUP(A5,部分股票代码!A:B,2,0) -> 603638.SH
A6: 森源电气 | B6: =VLOOKUP(A6,部分股票代码!A:B,2,0) -> 002358.SZ
A7: 昊志机电 | B7: =VLOOKUP(A7,部分股票代码!A:B,2,0) -> 300503.SZ
A8: 金一文化 | B8: F1002802.00
A9: 利民股份 | B9: =VLOOKUP(A9,部分股票代码!A:B,2,0) -> 002734.SZ
A10: 兰太实业 | B10: 600328.SH
A11: 维力医疗 | B11: =VLOOKUP(A11,部分股票代码!A:B,2,0) -> 603309.SH
A12: 金自天正 | B12: =VLOOKUP(A12,部分股票代码!A:B,2,0) -> 600560.SH
A13: 桂东电力 | B13: 600310.SH
A14: 吉艾科技 | B14: 300309.SZ
A15: 英特集团 | B15: =VLOOKUP(A15,部分股票代码!A:B,2,0) -> 000411.SZ
A16: 正虹科技 | B16: =VLOOKUP(A16,部分股票代码!A:B,2,0) -> 000702.SZ
A17: 亚太实业 | B17: =VLOOKUP(A17,部分股票代码!A:B,2,0) -> 000691.SZ
A18: 杭州高新 | B18: =VLOOKUP(A18,部分股票代码!A:B,2,0) -> 300478.SZ
A19: 凯瑞德 | B19: =VLOOKUP(A19,部分股票代码!A:B,2,0) -> 002072.SZ
A20: 天广消防 | B20: 002509.SZ
A21: 天马精化 | B21: 002453.SZ
A22: 嘉应制药 | B22: =VLOOKUP(A22,部分股票代码!A:B,2,0) -> 002198.SZ
A23: 凤形股份 | B23: =VLOOKUP(A23,部分股票代码!A:B,2,0) -> 002760.SZ
A24: 新日恒力 | B24: 600165.SH
A25: 道尔智控 | B25: =VLOOKUP(A25,部分股票代码!A:B,2,0) -> 832966.NQ
A26: 力盛运动 | B26: 002858.SZ
A27: 凤形股份 | B27: =VLOOKUP(A27,部分股票代码!A:B,2,0) -> 002760.SZ
A28: 当代东方 | B28: 000673.SZ
A29: 朗迪集团 | B29: =VLOOKUP(A29,部分股票代码!A:B,2,0) -> 603726.SH
A30: 丽岛新材 | B30: =VLOOKUP(A30,部分股票代码!A:B,2,0) -> 603937.SH
A31: 麦迪电气 | B31: 300341.SZ
A32: 初灵信息 | B32: =VLOOKUP(A32,部分股票代码!A:B,2,0) -> 300250.SZ
A33: 深桑达A | B33: =VLOOKUP(A33,部分股票代码!A:B,2,0) -> 000032.SZ
A34: 恒锋信息 | B34: =VLOOKUP(A34,部分股票代码!A:B,2,0) -> 300605.SZ
A35: 中广天择 | B35: =VLOOKUP(A35,部分股票代码!A:B,2,0) -> 603721.SH
A36: 天药股份 | B36: 600488.SH
A37: 华电重工 | B37: =VLOOKUP(A37,部分股票代码!A:B,2,0) -> 601226.SH
A38: 龙建股份 | B38: =VLOOKUP(A38,部分股票代码!A:B,2,0) -> 600853.SH
A39: 柏堡龙 | B39: 002776.SZ
A40: 长春燃气 | B40: =VLOOKUP(A40,部分股票代码!A:B,2,0) -> 600333.SH
...

Sheet 部分股票代码
A1: 证券简称 | B1: 证券代码
A2: 电光科技 | B2: 002730.SZ
A3: 美尚生态景观股份有限公司 | B3: F1007420.00
A4: 利德曼 | B4: 300289.SZ
A5: 艾迪精密 | B5: 603638.SH
A6: 森源电气 | B6: 002358.SZ
A7: 昊志机电 | B7: 300503.SZ
A8: 北京金一文化发展股份有限公司 | B8: F1002802.00
A9: 利民股份 | B9: 002734.SZ
A10: 维力医疗 | B10: 603309.SH
A11: 金自天正 | B11: 600560.SH
A12: 广西能源股份有限公司 | B12: F1001132.00
... A76: 广州粤泰集团股份有限公司 | B76: F1001162.00

Sheet 补充空白与2019
A1: 是 | B1: 是 | C1: 〔2024〕6号当事人:张顺平,男,1977年9月出生,住址:山东省潍坊市高新技术开发区。依据2005年修订、2014年修正的《中华人民共和国证券法》(以下简称2005年《证券法》)的有关规定,我会对张顺平操纵证券市场行为进行了立案调查、审理,并依法向当事人告知了作出行政处罚的事实、理由、依据及当事人依法享有的权利,当事人未提出陈述、申辩意见,也未要求听证。本案现已调查、审理终结。经查明,张顺平存在以下违法事实:一、控制使用证券账户的情况根据账户名义持有人指认、其他涉案人员陈述、账户开户资料及情况说明、借款协议、账户资金往来记录、账户交易流水、手机取证信息、账户交易终端信息(IP、MAC、硬盘序列号、下单手机号)等证据,2017年6月26日至9月29日期间,张顺平控制使用“韩某萍”财通证券账户等27个证券账户(以下称“账户组1”),交易“维格娜丝”等7只股票;2018年3月6日至4月27日期间,张顺平控制使用“庞某”财达证券账户等39个证券账户(以下称“账户组2”),交易“秦安股份”等4只股票。张顺平实际控制使用账户组所从事的涉案交易,由张顺平决策,由其实际操作下单或指派他人下单。二、张顺平操纵“维格娜丝”等11只股票的情况2017年6月26日至9月29日期间,张顺平控制使用“账户组1”,通过集中资金优势、持股优势连续买卖,虚假申报等手段,影响“维格娜丝”“金麒麟”“康隆达”“铁流股份”“红蜻蜓”“日月股份”“太平鸟”等7只股票交易价格和交易量;2018年3月6日至4月27日期间,张顺平控制使用“账户组2”,通过集中资金优势、持股优势连续买卖,在自己实际控制的账户之间进行证券交易(以下简称对倒交易),虚假申报等手段,影响“秦安股份”“上海亚虹”“恒润股份”“中马传动”等4只股票交易价格和交易量。具体情况如下:(一)操纵“维格娜丝”的情况1.2017年7月25日至8月14日操纵情况2017年7月25日至8月14日期间,张顺平控制使用“账户组1”,通过集中资金优势连续买卖、虚假申报等手段,影响“维格娜丝”交易价格和交易量,操纵市场。期间累计买入3,366,130股,累计买入金额81,148,242.15元;累计卖出3,366,130股,累计卖出金额81,254,769.32元。“账户组1”期初持有“维格娜丝”0股,期间期末持有0股。(1)集中资金优势连续买卖2017年7月25日至8月14日期间,“维格娜丝”共有15个交易日,“账户组1”共有15个交易日参与交易,占期间该股交易日总数的100%。“账户组1”申买量排名第一的有10个交易日,买成交量排名第一的有10个交易日,均占期间该股交易日总数的66.67%。“账户组1”买成交量占当日市场成交量比例的日均值为18.33%,超过20%有7个交易日,2017年8月7日占比最高,达48.68%。“账户组1”申卖量排名第一的有6个交易日,卖成交量排名第一的有5个交易日,分别占期间该股交易日总数的40%和33.33%。“账户组1”卖成交量占当日市场成交量比例的日均值为13.27%,超过20%有3个交易日,2017年8月8日占比最高,达71.28%。2017年7月25日至8月14日期间,“账户组1”以不低于市场卖一价或市价申买3,460,500股,占同期该账户组同向总申报量比例的日均值为88.24%,日最高占比值为100%;该类申买成交3,132,942股,占同期市场成交量比例的日均值为23.47%,日最高占比值为42.31%。在上述期间,“账户组1”有3个交易日存在盘中时段内股价涨幅2%以上且时段内买成交占比20%以上的情形。(2)虚假申报2017年7月25日至8月14日期间,张顺平控制使用“账户组1”,不以成交为目的,频繁申报、撤单,并进行与申报相反的交易。“账户组1”申买撤单量占该账户组申买量比例的日均值为11.82%,其中,2017年8月9日13:29:57至13:32:19期间,“账户组1”申买26笔,申买量为253,900股,“账户组1”申买量占市场申买量的78.68%,对应撤单量占“账户组1”申买量的55.03%,自申买开始后反向申报卖出且成交838,581股,成交金额20,202,817.53元。2017年7月25日至8月14日期间,“维格娜丝”股价走势较上证综指明显异常。该股2017年7月25日前一交易日收盘价23.25元,上述期间最高收盘价24.82元(2017年8月3日),较期初上涨6.75%,而同期上证综指涨幅0.69%,股价偏离上证综指6.06个百分点;期末(2017年8月14日)收盘价23.10元,较期初下跌0.65%,同期上证综指跌幅0.41%,股价偏离上证综指0.24个百分点。2.2017年8月23日至9月14日操纵情况2017年8月23日至9月14日期间,张顺平控制使用“账户组1”,通过集中资金优势、持股优势连续买卖的手段,影响“维格娜丝”交易价格和交易量,操纵市场。期间累计买入14,797,508股,累计买入金额386,760,816.44元;累计卖出14,797,508股,累计卖出金额388,322,464.48元。“账户组1”期初持有“维格娜丝”0股,期间期末持有0股。2017年8月23日至9月14日期间,“维格娜丝”共有17个交易日,“账户组1”共有17个交易日参与交易,占期间该股交易日总数的100%。“账户组1”申买量排名第一的有14个交易日,买成交量排名第一的有15个交易日,分别占期间该股交易日总数的82.35%和88.24%。“账户组1”买成交量占当日市场成交量比例的日均值为26.85%,超过20%有12个交易日,2017年8月28日占比最高,达59.04%。“账户组1”期初持股为0,从2017年8月23日开始买入,所持“维格娜丝”股票数量不断增加,在上述期间有3个交易日持股量占该股流通股本比例大于5%,2017年9月4日持股量最多,达3,614,480股,占该股流通股本的6.50%。“账户组1”申卖量排名第一的有12个交易日,卖成交量排名第一的有12个交易日,均占期间该股交易日总数的70.59%。“账户组1”卖成交量占当日市场成交量比例的日均值为22.17%,超过20%有9个交易日,2017年9月8日占比最高,达51.16%。2017年8月23日至9月14日期间,“账户组1”以不低于市场卖一价或市价申买18,656,500股,占同期“账户组1”同向总申报量的平均值为75.72%,日最高占比值为99.59%;该类申买成交13,589,408股,占同期市场成交量比例的日均值为28.35%,日最高占比值为59.02%。“账户组1”共有8个交易日存在盘中时段内股价涨幅2%以上且时段内买成交占比20%以上的情形。2017年8月23日至9月14日期间,“维格娜丝”股价走势较上证综指明显异常。该股2017年8月23日前一交易日收盘价23.85元,上述期间最高收盘价26.87元(2017年9月1日),较期初上涨12.66%,而同期上证综指涨幅2.34%,股价偏离上证综指10.32个百分点;期末(2017年9月14日)收盘价25.62元,较期初上涨7.42%,同期上证综指涨幅2.47%,股价偏离上证综指4.95个百分点。经统计,张顺平通过“账户组1”交易“维格娜丝”盈利900,505.92元。(二)操纵“康隆达”的情况2017年9月20日至9月29日期间,张顺平控制使用“账户组1”,通过集中资金优势、持股优势连续买卖的手段,影响“康隆达”交易价格和交易量,操纵市场。期间“账户组1”累计买入2,357,198股,买入金额92,089,376.68元;累计卖出2,357,198股,卖出金额92,752,209.95元。“账户组1”期初持有“康隆达”0股,期间期末持有0股。2017年9月20日至9月29日期间,“康隆达”共有8个交易日,“账户组1”共有8个交易日参与交易,占期间该股交易日总数的100%。“账户组1”申买量排名第一的有7个交易日,买成交量排名第一的有4个交易日,分别占期间该股交易日总数的87.50%和50%。“账户组1”买成交量占当日市场成交量比例的日均值为15.60%,超过20%有2个交易日,2017年9月20日占比最高,达40.87%。“账户组1”期初持股为0,从2017年9月20日开始买入,所持“康隆达”股票数量不断增加,2017年9月22日持股量达1,361,020股,占该股流通股本的5.44%。“账户组1”申卖量排名第一的有2个交易日,卖成交量排名第一的有2个交易日,均占期间该股交易日总数的25%。“账户组1”卖成交量占当日市场成交量比例的日均值为11.70%,超过20%有2个交易日,2017年9月27日占比最高,达38.47%。2017年9月20日至9月29日期间,“账户组1”以不低于市场卖一价或市价申买2,779,200股,占同期“账户组1”同向总申报量比例的日均值为70.79%,日最高占比值为99.38%;该类申买成交1,987,113股,占同期市场成交量比例的日均值为17.84%,日最高占比值为35.65%。“账户组1”共有3个交易日存在盘中时段内股价涨幅2%以上且时段内买成交占比20%以上的情形。2017年9月20日至9月29日期间,“康隆达”股价走势较上证综指明显异常。该股2017年9月20日前一交易日收盘价37.12元,期间最高收盘价39.82元(2017年9月22日),较期初上涨7.27%,同期上证指数跌幅为0.13%,股价偏离上证综指7.40个百分点。期末(2017年9月29日)收盘价36.46元,较期初下跌1.78%,同期上证综指跌幅0.24%,股价偏离上证综指1.54个百分点。经统计,张顺平通过“账户组1”交易“康隆达”盈利512,617.73元。(三)操纵“金麒麟”的情况1.2017年8月22日至8月31日操纵情况2017年8月22日至8月31日期间,张顺平控制使用“账户组1”,通过集中资金优势连续买卖、虚假申报等手段,影响“金麒麟”交易价格和交易量,操纵市场。期间累计买入2,594,495股,累计买入金额79,808,907.69元;累计卖出2,594,495股,累计卖出金额81,081,823.44元。“账户组1”期初持有“金麒麟”0股,期间期末持有0股。2017年8月22日至8月31日期间,“金麒麟”共有8个交易日,“账户组1”共有8个交易日参与交易,占期间该股交易日总数的100%。“账户组1”申买量排名第一的有6个交易日,买成交量排名第一的有6个交易日,均占期间该股交易日总数的75%。“账户组1”买成交量占当日市场成交量比例的日均值为7.61%,超过20%有1个交易日,2017年8月25日占比达23.05%。“账户组1”申卖量排名第一的有4个交易日,卖成交量排名第一的有4个交易日,均占期间该股交易日总数的50%。“账户组1”卖成交量占当日市场成交量比例的日均值为6.66%,超过20%有1个交易日,2017年8月29日占比达21.77%。2017年8月22日至8月31日期间,“账户组1”以不低于市场卖一价或市价申买2,928,500股,占同期“账户组1”同向总申报量比例的日均值为89.57%,日最高占比值为100%;该类申买成交2,495,595股,占同期市场成交量比例的日均值为9.90%,日最高占比值为22.96%。2017年8月22日至8月31日期间,“金麒麟”股价走势较上证综指明显异常。该股2017年8月22日前一交易日收盘价30.11元,期间最高收盘价31.59元(2017年8月29日),较期初上涨4.92%,而同期上证综指涨幅2.38%,与同期上证综指偏离2.54个百分点。期末(2017年8月31日)收盘价31.55元,较期初上涨4.78%,同期上证综指涨幅2.25%,股价偏离上证综指2.53个百分点。2.2017年9月4日至9月22日操纵情况2017年9月4日至9月22日期间,张顺平控制使用“账户组1”,通过集中资金优势、持股优势连续买卖,虚假申报的手段,影响“金麒麟”交易价格和交易量,操纵市场。期间累计买入6,760,666股,累计买入金额221,119,994.94元;累计卖出6,760,666股,累计卖出金额223,864,885.75元。“账户组1”期初持有“金麒麟”0股,期间期末持有0股。(1)集中资金优势、持股优势连续买卖2017年9月4日至9月22日期间,“金麒麟”共有15个交易日,“账户组1”共有15个交易日参与交易,占期间该股交易日总数的100%。“账户组1”申买量排名第一的有12个交易日,买成交量排名第一的有11个交易日,分别占期间该股交易日总数的80%和73.33%。“账户组1”买成交量占当日市场成交量比例的日均值为10.78%,超过20%有1个交易日,2017年9月7日占比达29.11%。账户组1”期初持股为0,从2017年9月4日开始买入,所持“金麒麟”股票数量不断增加,上述期间有4个交易日持股量占该股流通股本比例大于5%,2017年9月18日持股量达3,290,743股,占该股流通股本的6.27%。“账户组1”申卖量排名第一的有7个交易日,卖成交量排名第一的有8个交易日,分别占期间该股交易日总数的46.67%和53.33%。“账户组1”卖成交量占当日市场成交量比例的日均值为8.24%,超过20%有2个交易日,2017年9月19日占比最高,达39.93%。2017年9月4日至9月22日期间,“账户组1”以不低于市场卖一价或市价申买8,383,900股,占同期“账户组1”同向总申报量比例的日均值为71.95%,日最高占比值为100%;该类申买成交6,086,705股,占同期市场成交量比例的日均值为11.47%,日最高占比值为29.18%。“账户组1”共有6个交易日存在盘中时段内股价涨幅2%以上且时段内买成交占比20%以上的情形。(2)虚假申报2017年9月4日至9月22日期间,张顺平控制使用“账户组1”,不以成交为目的,频繁申报、撤单,并进行与申报相反的交易。“账户组1”买入撤单量占“账户组1”申买量的日均比例为28.75%。其中,2017年9月13日9:15:03至14:58:07期间,“账户组1”申买506笔,申买量为2,551,100股,“账户组1”申买量占市场申买量的33.19%,对应撤单量占“账户组1”申买量的55.84%,自申买开始后反向申报卖出且成交643,900股,成交金额21,291,622.10元。2017年9月20日9:15:02至9:54:10期间,“账户组1”申买123笔,申买量为906,200股,“账户组1”申买量占市场申买量的43.72%,撤单量占“账户组1”申买量的76.70%,自申买开始后反向申报卖出且成交1,278,733股,成交金额42,662,057.88元。2017年9月4日至9月22日期间,“金麒麟”股价走势较上证综指明显异常。该股2017年9月4日前一交易日收盘价31.30元,期间最高收盘价34.06元(2017年9月18日),较期初上涨8.82%,而同期上证综指下跌0.13%,股价偏离上证综指8.95个百分点。期末(2017年9月22日)收盘价31.53元,较期初上涨0.73%,同期上证综指跌幅0.43%,股价偏离上证综指1.16个百分点。经统计,张顺平通过“账户组1”交易“金麒麟”盈利3,538,398.15元。(四)操纵“铁流股份”的情况2017年8月15日至8月25日期间,张顺平控制使用“账户组1”,通过集中资金优势、持股优势连续买卖,虚假申报等手段,影响“铁流股份”交易价格和交易量,操纵市场。期间“账户组1”累计买入6,819,267股,买入金额211,254,876.64元;累计卖出6,819,267股,卖出金额213,865,254.66元。“账户组1”期初持有“铁流股份”0股,期间期末持有0股。1.集中资金优势、持股优势连续买卖2017年8月15日至8月25日期间,“铁流股份”共有9个交易日,“账户组1”共有9个交易日参与交易,占期间该股交易日总数的100%。“账户组1”申买量排名第一的有8个交易日,买成交量排名第一的有8个交易日,占期间该股交易日总数的88.89%。“账户组1”买成交量占当日市场成交量比例的日均值为20.83%,超过20%有4个交易日,2017年8月17日占比最高,达44.03%。“账户组1”期初持股为0,从2017年8月15日开始买入,所持“铁流股份”股票数量不断增加,上述期间有3个交易日持股量占该股流通股本比例大于5%,2017年8月21日持股量达3,094,731股,占该股流通股本的10.32%。“账户组1”申卖量排名第一的有6个交易日,卖成交量排名第一的有6个交易日,均占期间该股交易日总数的66.67%。“账户组1”卖成交量占当日市场成交量比例的日均值为18.50%,超过20%有5个交易日,2017年8月22日占比最高,达50.89%。2017年8月15日至8月25日期间,“账户组1”以不低于市场卖一价或市价申买7,094,200股,占同期“账户组1”同向总申报量比例的日均值为71.52%,日最高占比值为93.31%;该类申买成交6,238,185股,占同期市场成交量比例的日均值为21.20%,日最高占比值为39.94%。“账户组1”共有5个交易日存在盘中时段内股价涨幅2%以上且时段内买成交占比20%以上的情形。2.虚假申报2017年8月15日至8月25日期间,张顺平控制使用“账户组1”,不以成交为目的,频繁申报、撤单,并进行与申报相反的交易。“账户组1”买入撤单量占“账户组1”申买量的日均比例为28.75%。其中,2017年8月24日9:15:02至9:30:02期间,“账户组1”申买3笔,申买量为221,900股,“账户组1”申买量占市场申买量的75.79%,对应撤单量占“账户组1”申买量的100%,自申买开始后反向申报卖出且成交539,869股,成交金额16,206,354.79元。2017年8月15日至8月25日,“铁流股份”股价走势较上证综指明显异常。该股2017年8月15日前一交易日收盘价28.31元,期间最高收盘价32.62元(2017年8月21日),较期初上涨15.22%,而同期上证综指涨幅1.53%,股价偏离上证综指13.69个百分点。期末(2017年8月25日)收盘价29.96元,较期初上涨5.83%,同期上证综指涨幅2.91%,股价偏离上证综指2.92个百分点。经统计,张顺平通过“账户组1”交易“铁流股份”盈利2,128,721.93元。(五)操纵“红蜻蜓”的情况1.2017年7月24日至8月2日操纵情况2017年7月24日至8月2日期间,张顺平控制使用“账户组1”,通过集中资金优势连续买卖、虚假申报等手段,影响“红蜻蜓”交易价格和交易量,操纵市场。期间“账户组1”累计买入7,891,653股,累计买入金额140,684,332.36元;累计卖出7,891,653股,累计卖出金额141,270,129.78元。“账户组1”期初持有“红蜻蜓”0股,期间期末持有0股。(1)集中资金优势连续买卖2017年7月24日至8月2日期间,“红蜻蜓”共有8个交易日,“账户组1”共有8个交易日参与交易,占期间该股交易日总数的100%。“账户组1”申买量排名第一的有6个交易日,买成交量排名第一的有6个交易日,均占期间该股交易日总数的75%。“账户组1”买成交量占当日市场成交量比例的日均值为22.19%,超过20%有5个交易日,2017年7月24日占比最高,达43.07%。“账户组1”申卖量排名第一的有6个交易日,卖成交量排名第一的有6个交易日,均占期间该股交易日总数的75%。2017年7月24日至8月2日期间,“账户组1”以不低于市场卖一价或市价申买8,978,100股,占同期“账户组1”同向总申报量比例的日均值为67.54%,日最高占比值为91.33%;该类申买成交7,466,852股,占同期市场成交量比例的日均值为24.06%,日最高占比值为41.82%。“账户组1”共有4个交易日存在盘中时段内股价涨幅2%以上且时段内买成交占比20%以上的情形。(2)虚假申报2017年7月24日至8月2日期间,张顺平控制使用“账户组1”,不以成交为目的,频繁申报、撤单,并进行与申报相反的交易。“账户组1”买入撤单量占“账户组1”申买量的日均比例为34.24%。其中,2017年7月28日9:23:26至13:02:51期间,“账户组1”申买118笔,申买量为1,233,800股,“账户组1”申买量占市场申买量的35.02%,对应撤单量占“账户组1”申买量的57.57%,自申买开始后反向申报卖出且成交2,299,500股,成交金额41,448,113.00元。2017年8月1日13:27:56至13:28:08期间,“账户组1”申买2笔,申买量为55,100股,“账户组1”申买量占市场申买量的98.39%,对应撤单量达到“账户组1”申买量的100%,自申买开始后反向申报卖出且成交147,074股,成交金额2,602,400.36元。2017年7月24日至8月2日期间,“红蜻蜓”股价走势较上证综指明显异常。该股2017年7月24日前一交易日收盘价17.07元,期间最高收盘价18.14元(2017年7月27日),较期初上涨6.27%,而同期上证综指涨幅0.36%,股价偏离上证综指偏离5.91个百分点。期末(2017年8月2日)收盘价17.34元,较期初上涨1.58%,同期上证综指涨幅1.45%,股价偏离上证综指0.13个百分点。2.2017年8月31日至9月8日操纵情况2017年8月31日至9月8日期间,张顺平控制使用“账户组1”,通过集中资金优势连续买卖的手段,影响“红蜻蜓”交易价格和交易量,操纵市场。期间“账户组1”累计买入2,925,600股,累计买入金额52,563,947.74元;累计卖出2,925,600股,累计卖出金额52,493,007.00元。“账户组1”期初持有“红蜻蜓”0股,期间期末持有0股。2017年8月31日至9月8日期间,“红蜻蜓”共有7个交易日,“账户组1”共有7个交易日参与交易,占期间该股交易日总数的100%。“账户组1”申买量排名第一的有3个交易日,买成交量排名第一的有3个交易日,均占期间该股交易日总数的42.86%。“账户组1”买成交量占当日市场成交量比例的日均值为9.68%,超过20%有2个交易日,2017年9月1日占比最高,达28.64%。“账户组1”申卖量排名第一的有2个交易日,卖成交量排名第一的有2个交易日,均占期间该股交易日总数的28.57%。“账户组1”卖成交量占当日市场成交量比例的日均值为11.27%,超过20%有2个交易日,2017年9月4日占比最高,达46.41%。2017年8月31日至9月8日期间,“账户组1”以不低于市场卖一价或市价申买2,955,300股,占同期“账户组1”同向总申报量比例的日均值为98.55%,日最高占比值为99.22%;该类申买成交2915500股,占同期市场成交量比例的日均值为22.53%,日最高占比值为28.63%。该股2017年8月31日前一交易日收盘价17.70元,期间最高收盘价18.13元(2017年9月1日),较期初上涨2.43%,而同期上证综指涨幅0.10%,股价偏离上证综指2.33个百分点。期末(2017年9月8日)收盘价17.88元,较期初上涨1.02%,同期上证综指涨幅0.05%,股价偏离上证综指0.97个百分点。经统计,张顺平通过“账户组1”交易“红蜻蜓”盈利127,659.28元。(六)操纵“日月股份”的情况2017年7月20日至7月26日期间,张顺平控制使用“账户组1”,通过集中资金优势连续买卖、虚假申报的手段,影响“日月股份”交易价格和交易量,操纵市场。期间“账户组1”累计买入2,685,999股,累计买入金额86,377,979.88元;累计卖出2,685,999股,累计卖出金额88,682,811.24元。“账户组1”期初持有“日月股份”0股,期间期末持有0股。1.集中资金优势连续买卖2017年7月20日至7月26日期间,“日月股份”共有5个交易日,“账户组1”共有5个交易日参与交易,占期间该股交易日总数的100%。“账户组1”申买量排名第一的有4个交易日,买成交量排名第一的有4个交易日,均占期间该股交易日总数的80%。“账户组1”买成交量占当日市场成交量比例的日均值为18.03%,超过20%有3个交易日,2017年7月24日占比最高,达35.22%。“账户组1”申卖量排名第一的有3个交易日,卖成交量排名第一的有4个交易日,分别占期间该股交易日总数的60%和80%。“账户组1”卖成交量占当日市场成交量比例的日均值为13.46%,超过20%有1个交易日,2017年7月25日占比达42.16%。2017年7月20日至7月26日期间,“账户组1”以不低于市场卖一价或市价申买4,012,500股,占同期“账户组1”同向总申报量比例的日均值为79.38%,日最高占比值为92.40%;该类申买成交2,574,099股,占同期市场成交量比例的日均值为21.62%,日最高占比值为33.78%。“账户组1”共有4个交易日存在盘中时段内股价涨幅2%以上且时段内买成交占比20%以上的情形。2.虚假申报2017年7月20日至7月26日期间,张顺平控制使用“账户组1”,不以成交为目的,频繁申报、撤单,并进行与申报相反的交易。“账户组1”申买撤单量占“账户组1”申买量的日均比例为35.73%。其中,2017年7月21日9:15:02至14:57:51期间,“账户组1”申买403笔,申买量为1,740,200股,“账户组1”申买量占市场申买量的33.86%,对应撤单量占“账户组1”申买量的55.20%,自申买开始后反向申报卖出且成交267,252股,成交金额8,555,173.29元。2017年7月24日9:19:14至14:59:04期间,“账户组1”申买362笔,申买量为2,213,400股,“账户组1”申买量占市场申买量的43.51%,对应撤单量占“账户组1”申买量的56.54%,自申买开始后反向申报卖出且成交202,200股,成交金额6,676,962.00元。2017年7月25日9:15:03至9:33:04期间,“账户组1”申买10笔,申买量为149,800股,“账户组1”申买量占市场申买量的55.85%,对应撤单量占“账户组1”申买量的96.06%,自申买开始后反向申报卖出且成交1,975,347股,成交金额65,650,923.67元。2017年7月20日至7月26日期间,“日月股份”股价走势较上证综指明显异常。该股2017年7月20日前一交易日收盘价30.48元,期间最高收盘价33.26元(2017年7月25日),较期初上涨9.12%,而同期上证综指涨幅0.39%,股价偏离上证综指8.73个百分点。期末(2017年7月26日)收盘价31.68元,较期初上涨3.94%,同期上证综指涨幅0.52%,股价偏离上证综指3.42个百分点。经统计,张顺平通过“账户组1”交易“日月股份”盈利2,160,131.60元。(七)操纵“太平鸟”的情况1.2017年6月26日至7月7日操纵情况2017年6月26日至7月7日期间,张顺平控制使用“账户组1”,通过集中资金优势连续买卖的手段,影响“太平鸟”交易价格和交易量,操纵市场。期间“账户组1”累计买入1,341,057股,累计买入金额36,652,408.66元;累计卖出1,341,057股,累计卖出金额38,269,837.44元。“账户组1”期初持有“太平鸟”0股,期间期末持有0股。2017年6月26日至7月7日期间,“太平鸟”共有10个交易日,“账户组1”共有8个交易日参与交易,占期间该股交易日总数的80%。“账户组1”申买量排名第一的有4个交易日,买成交量排名第一的有4个交易日,均占期间该股交易日总数的40%。“账户组1”买成交量占当日市场成交量比例的日均值为6.46%,2017年6月28日占比最高,达17.64%。“账户组1”申卖量排名第一的有3个交易日,卖成交量排名第一的有4个交易日,分别占期间该股交易日总数的30%和40%。“账户组1”卖成交量占当日市场成交量比例的日均值为3.55%,2017年7月5日占比最高,达11.77%。2017年6月26日至7月7日期间,“账户组1”以不低于市场卖一价或市价申买1,118,200股,占同期“账户组1”同向总申报量比例的日均值为49.51%,日最高占比值为74.27%;该类申买成交1,097,222股,占同期市场成交量比例的日均值为6.77%,日最高占比值为12.35%。2017年6月26日至7月7日期间,“太平鸟”股价走势较上证综指明显异常。该股2017年6月26日前一交易日收盘价26.78元,期间最高收盘价28.71元(2017年7月5日),较期初上涨7.21%,而同期上证综指涨幅1.56%,股价偏离上证综指5.65个百分点。期末(2017年7月7日)收盘价28.10元,较期初上涨4.93%,同期上证综指涨幅1.90%,股价偏离上证综指3.03个百分点。2.2017年7月20日至7月28日操纵情况2017年7月20日至7月28日期间,张顺平控制使用“账户组1”,通过集中资金优势连续买卖的手段,影响“太平鸟”交易价格和交易量,操纵市场。期间“账户组1”累计买入1,511,013股,累计买入金额38,387,728.69元;累计卖出1,511,013股,累计卖出金额39,089,971.45元。“账户组1”期初持有“太平鸟”0股,期间期末持有0股。2017年7月20日至7月28日期间,“太平鸟”共有7个交易日,“账户组1”共有7个交易日参与交易,占期间该股交易日总数的100%。“账户组1”申买量排名第一的有2个交易日,买成交量排名第一的有4个交易日,分别占期间该股交易日总数的28.57%和57.14%。“账户组1”买成交量占当日市场成交量比例的日均值为8.96%,超过20%有1个交易日,2017年7月26日占比最高,达28.94%。“账户组1”申卖量排名第一的有2个交易日,卖成交量排名第一的有3个交易日,分别占期间该股交易日总数的28.57%和42.86%。2017年7月20日至7月28日期间,“账户组1”以不低于市场卖一价或市价申买1,706,200股,占同期“账户组1”同向总申报量比例的日均值为93.46%,日最高占比值为99.32%;该类申买成交1,442,113股,占同期市场成交量比例的日均值为12.08%,日最高占比值为28.17%。“账户组1”共有2个交易日存在盘中时段内股价涨幅2%以上且时段内买成交占比20%以上的情形。2017年7月20日至7月28日期间,“太平鸟”股价走势较上证综指明显异常。该股2017年7月20日前一交易日收盘价25.08元,期间最高收盘价26.24元(2017年7月26日),较期初上涨4.63%,而同期上证综指涨幅0.52%,股价偏离上证综指4.11个百分点。期末(2017年7月28日)收盘价25.26元,较期初上涨0.72%,同期上证综指涨幅0.69%,股价偏离上证综指0.03个百分点。经统计,张顺平通过“账户组1”交易“太平鸟”盈利2,192,927.56元。(八)操纵“秦安股份”的情况2018年3月13日至4月3日,张顺平控制使用“账户组2”,通过集中资金优势、持股优势连续买卖,对倒交易,虚假申报等手段,影响“秦安股份”交易价格和交易量,操纵市场。期间累计买入18,228,186股,累计买入金额247,520,492.27元;累计卖出18,228,186股,累计卖出金额249,653,622.86元。“账户组2”期初持有“秦安股份”0股,期间期末持有0股。1.集中资金优势、持股优势连续买卖2018年3月13日至4月3日期间,“秦安股份”共有16个交易日,“账户组2”共有16个交易日参与交易,占期间该股交易日总数的100%。“账户组2”累计竞价买入成交15,150,590股(扣除对倒成交量),累计竞价卖出成交15,150,590股(扣除对倒成交量)。“账户组2”申买量排名第一的有15个交易日,买成交量排名第一的有13个交易日,分别占期间该股交易日总数的93.75%和81.25%。“账户组2”买成交量占当日市场成交量的日均值为22.50%,超过20%的有10个交易日,2018年3月19日占比最高,达48.65%。“账户组2”期初持股为0,从2018年3月13日开始买入,所持“秦安股份”股票数量不断增加,期间有7个交易日持股量占该股流通股本比例大于5%,有3个交易日持股量占该股流通股本比例大于10%,2018年3月23日持股量最多,达7,203,281股,占该股流通股本的12.01%。“账户组2”申卖量排名第一的有11个交易日,卖成交量排名第一的有11个交易日,均占期间该股交易日总数的68.75%。“账户组2”卖成交量占当日市场成交量比例的日均值为18.65%,超过20%的有6个交易日,2018年3月27日占比最高,达61.34%。2018年3月13日至4月3日期间,“账户组2”以不低于市场卖一价或市价申买20,304,100股,占同期账户组同向总申报量比例的日均值为60.30%,日最高占比值为98.26%;该类申买成交15,052,786股,占同期市场成交量比例的日均值为19.95%,日最高占比值为42.41%。在上述期间,“账户组2”共有9个交易日存在盘中时段内股价涨幅2%以上且时段内买成交占比20%以上的情形。2.对倒交易2018年3月13日至4月3日期间,当事人共有13个交易日在自己实际控制的账户之间交易“秦安股份”,成交量3,077,596股;其中,有1个交易日在自己实际控制的账户之间交易的成交量占当日市场成交量的比例大于10%,2018年3月22日占比达21.34%。3.虚假申报2018年3月13日至4月3日期间,张顺平控制使用“账户组2”,不以成交为目的,频繁申报、撤单,并进行与申报相反的交易。“账户组2”申买撤单量占“账户组2”申买量比例的日均值为31.54%。其中,2018年3月29日9:15:01至13:59:02期间,“账户组2”申买2,423笔,申买量为4,416,800股,“账户组2”申买量占市场申买量的42.15%,对应撤单量占“账户组2”申买量的53.50%,自申买开始后反向申报卖出且成交3,330,063股,成交金额45,674,621.14元;2018年3月30日9:15:01至10:31:37期间,“账户组2”申买790笔,申买量为1,973,900股,“账户组2”申买量占市场申买量的34.36%,对应撤单量占“账户组2”申买量的85.91%,自申买开始后反向申报卖出且成交1,605,720股,成交金额21,784,014.43元;2018年4月2日9:22:36至9:30:57期间,“账户组2”申买38笔,申买量为696,300股,“账户组2”申买量占市场申买量的73.54%,对应撤单量占“账户组2”申买量的99.87%,自申买开始后反向申报卖出且成交188,200股,成交金额2,522,185.95元。2018年3月13日至4月3日期间,“秦安股份”股价走势较上证综指明显异常,该股2018年3月13日前一交易日收盘价12.52元,上述期间最高收盘价14.33元(2018年3月20日),较期初上涨14.46%,而同期上证综指跌幅1.08%,股价偏离上证综15.54个百分点;期末(2018年4月3日)收盘价12.36元,较期初上涨1.92%,同期上证指数跌幅5.71%,股价偏离上证综指7.63个百分点。经统计,张顺平通过“账户组2”交易“秦安股份”盈利1,741,415.47元。(九)操纵“上海亚虹”的情况2018年3月9日至3月16日期间,张顺平控制使用“账户组2”,通过集中资金优势、持股优势连续买卖手段,影响“上海亚虹”交易价格和交易量,操纵市场。期间累计买入1,980,778股,累计买入金额47,122,545.36元;累计卖出1,980,778股,累计卖出金额49,174,430.06元。“账户组2”期初持有“上海亚虹”0股,期间期末持有0股。2018年3月9日至3月16日期间,“上海亚虹”共有6个交易日,“账户组2”共有6个交易日参与交易,占期间该股交易日总数的100%。“账户组2”申买量排名第一的有4个交易日,买成交量排名第一的有3个交易日,分别占期间该股交易日总数的66.67%和50%。“账户组2”买成交量占当日市场成交量比例的日均值为15.04%,超过20%的有2个交易日,2018年3月9日占比最高,达29.12%。“账户组2”期初持股为0,从2018年3月9日开始买入,所持“上海亚虹”股票数量不断增加,操纵期间有1个交易日持股量占该股流通股本比例大于5%,2018年3月12日持股量最多,达1,362,378股,占该股流通股本的5.45%。“账户组2”申卖量排名第一的有2个交易日,卖成交量排名第一的有2个交易日,均占期间该股交易日总数的33.33%。“账户组2”卖成交量占当日市场成交量比例的日均值为14.59%,超过20%的有2个交易日,2018年3月13日占比最高,达38.78%。2018年3月9日至3月16日期间,“账户组2”以不低于市场卖一价或市价申买1,954,500股,占同期账户组同向总申报量比例的日均值为53.89%,日最高占比值为100%;该类申买成交1,630,378股,占同期市场成交量比例的日均值为12.53%,日最高占比值为28.73%。在上述期间,“账户组2”共有3个交易日存在盘中时段内股价涨幅2%以上且时段内买成交占比20%以上的情形。2018年3月9日至3月16日期间,“上海亚虹”股价走势较上证综指明显异常,该股2018年3月9日前一交易日收盘价21.53元,上述期间最高收盘价25.27元(2018年3月12日),较期初上涨17.37%,而同期上证综指涨幅1.16%,股价偏离上证综指16.21个百分点;期末(2018年3月16日)收盘价22.38元,较期初上涨3.95%,同期上证指数跌幅0.56%,股价偏离上证综指4.51个百分点。经统计,张顺平通过“账户组2”交易“上海亚虹”盈利1,977,487.20元。(十)操纵“恒润股份”的情况2018年4月2日至4月25日期间,张顺平控制使用“账户组2”,通过集中资金优势、持股优势连续买卖,对倒交易,虚假申报等手段,影响“恒润股份”交易价格和交易量,操纵市场。期间累计买入12,523,172股,累计买入金额479,615,116.96元;累计卖出12,312,172股,累计卖出金额467,356,984.35元。账户组期初持有“恒润股份”0股,期末持有211,000股。1.集中资金优势、持股优势连续买卖2018年4月2日至4月25日期间,“恒润股份”共有16个交易日,“账户组2”共有16个交易日参与交易,占期间该股交易日总数的100%。“账户组2”累计竞价买入成交10,328,629股(扣除对倒成交量);累计竞价卖出成交10,117,629股(扣除对倒成交量)。“账户组2”申买量排名第一的有15个交易日,买成交量排名第一的有14个交易日,分别占期间该股交易日总数的93.75%和87.5%。“账户组2”买成交量占当日市场成交量比例的日均值为32.02%,超过20%的有13个交易日,2018年4月10日占比最高,达49.05%。“账户组2”期初持股为0,从2018年4月2日开始买入,所持“恒润股份”股票数量不断增加,期间有10个交易日持股量占该股流通股本比例大于5%,有7个交易日持股量占该股流通股本比例大于10%,2018年4月10日持股量最多,达3,419,043股,占该股流通股本的17.1%。“账户组2”申卖量排名第一的有14个交易日,卖成交量排名第一的有15个交易日,分别占期间该股交易日总数的87.5%和93.75%。“账户组2”卖成交量占当日市场成交量比例的日均值为29.67%,超过20%的有8个交易日,2018年4月17日占比最高,达62.66%。2018年4月2日至4月25日期间,“账户组2”以不低于市场卖一价或市价申买14,248,200股,占同期账户组同向总申报量比例的日均值为57.36%,日最高占比值为98.00%;该类申买成交10,518,272股,占同期市场成交量比例的日均值为27.10%,日最高占比值为42.46%。在上述期间,“账户组2”共有11个交易日存在盘中时段内股价涨幅2%以上且时段内买成交占比20%以上的情形。2.对倒交易2018年4月2日至4月25日期间,当事人共有14个交易日在自己实际控制的账户之间交易“恒润股份”,成交量2,194,543股;其中,有2个交易日在自己实际控制的账户之间交易的成交量占当日市场成交量的比例大于10%,2018年4月13日占比最高,达14.4%。3.虚假申报2018年4月2日至4月25日期间,张顺平控制使用“账户组2”,不以成交为目的,频繁申报、撤单,并进行与申报相反的交易。“账户组2”申买撤单量占“账户组2”申买量比例的日均值为25.72%。其中,2018年4月24日9:15:00至10:24:22期间,“账户组2”申买306笔,申买量为858,300股,“账户组2”申买量占市场申买量的54.83%,对应撤单量占“账户组2”申买量的95.36%,自申买开始后反向申报卖出且成交242,200股,成交金额8,198,625.00元。2018年4月2日至4月25日期间,“恒润股份”股价走势较上证综指明显异常,该股2018年4月2日前一交易日收盘价32.54元,上述期间最高收盘价40.52元(2018年4月11日),较期初上涨24.52%,而同期上证综指涨幅1.24%,股价偏离上证综指23.28个百分点;期末(2018年4月25日)收盘价34.1元,较期初上涨4.79%,同期上证指数跌幅1.61%,股价偏离上证综指6.40个百分点。经统计,张顺平通过“账户组2”交易“恒润股份”亏损6,302,121.55元。(十一)操纵“中马传动”的情况2018年3月6日至4月11日期间,张顺平控制使用“账户组2”,通过集中资金优势、持股优势连续买卖,对倒交易,虚假申报等手段,影响“中马传动”交易价格和交易量,操纵市场。期间累计买入17,605,196股,累计买入金额254,263,943.10元;累计卖出17,605,196股,累计卖出金额260,247,279.70元。“账户组2”期初持有“中马传动”0股,期间期末持有0股。1.集中资金优势、持股优势连续买卖2018年3月6日至4月11日期间,“中马传动”共有25个交易日,“账户组2”共有25个交易日参与交易,占期间该股交易日总数的100%。“账户组2”累计竞价买入成交15,237,582股(扣除对倒成交量);累计竞价卖出成交15,237,582股(扣除对倒成交量)。“账户组2”申买量排名第一的有20个交易日,买成交量排名第一的有21个交易日,分别占期间该股交易日总数的80%和84%。“账户组2”买成交量占当日市场成交量比例的日均值为17.41%,超过20%的有10个交易日,2018年3月20日占比最高,达39.60%。“账户组2”期初持股为0,从2018年3月6日开始买入,所持“中马传动”股票数量不断增加,期间有2个交易日持股量占该股流通股本比例大于5%,有1个交易日持股量占该股流通股本比例大于10%,2018年4月2日持股量最多,达5,861,833股,占该股流通股本的10.99%。“账户组2”申卖量排名第一的有17个交易日,卖成交量排名第一的有16个交易日,分别占期间该股交易日总数的68%和64%。“账户组2”卖成交量占当日市场成交量比例的日均值为13.58%,超过20%的有6个交易日,2018年4月3日占比最高,达45.82%。2018年3月6日至4月11日期间,“账户组2”以不低于市场卖一价或市价申买18,339,800股,占同期账户组同向总申报量比例的日均值为68.81%,日最高占比值为100%;该类申买成交15,194,149股,占同期市场成交量比例的日均值为14.34%,日最高占比值为33.75%。在上述期间,账户组共有10个交易日存在盘中时段内股价涨幅2%以上且时段内买成交占比20%以上的情形。2.对倒交易2018年3月6日至4月11日期间,当事人共有17个交易日在自己实际控制的账户之间交易“中马传动”,成交量2,367,614股;其中,有3个交易日在自己实际控制的账户之间交易的成交量占当日市场成交量的比例大于10%,2018年3月20日占比最高,达31.61%。3.虚假申报2018年3月6日至4月11日期间,张顺平控制使用“账户组2”,不以成交为目的,频繁申报、撤单,并进行与申报相反的交易。“账户组2”申买撤单量占“账户组2”申买量比例的日均值为23.74%。其中,2018年3月8日11:21:50至13:19:49期间,“账户组2”申买7笔,申买量为100,300股,“账户组2”申买量占市场申买量的31.89%,对应撤单量占“账户组2”申买量的83.13%,自申买开始后反向申报卖出且成交213,300股,金额2,840,885.00元。2018年3月12日13:03:47至13:07:28期间,“账户组2”申买3笔,申买量为17,400股,“账户组2”申买量占市场申买量的38.33%,对应撤单量占“账户组2”申买量的69.54%,自申买开始后反向申报卖出且成交1,089,124股,金额15,504,154.88元。2018年3月22日9:15:03至13:15:12期间,“账户组2”申买947笔,申买量为2,456,500股,“账户组2”申买量占市场申买量的35.94%,对应撤单量占“账户组2”申买量的54.43%,自申买开始后反向申报卖出且成交2,051,647股,金额28,894,229.47元。2018年3月23日9:15:02至10:32:54期间,“账户组2”申买731笔,申买量为1,466,200股,“账户组2”申买量占市场申买量的36.98%,对应撤单量占“账户组2”申买量的77.24%,自申买开始后反向申报卖出且成交748,147股,金额10,478,398.65元。2018年4月4日9:15:03至14:10:59期间,“账户组2”申买1,659笔,申买量为3,956,700股,“账户组2”申买量占市场申买量的34.60%,对应撤单量占“账户组2”申买量的60.32%,自申买开始后反向申报卖出且成交2,107,215股,金额32,098,118.17元。2018年3月6日至4月11日期间,“中马传动”股价走势较上证综指明显异常,该股2018年3月6日前一交易日收盘价13.16元,上述期间最高收盘价16.04元(2018年4月11日),较期初上涨21.88%,而同期上证综指跌幅1.50%,股价偏离上证综指23.38个百分点;期末(2018年4月11日)收盘价16.04元,较期初上涨21.88%,同期上证指数跌幅1.50%,股价偏离上证综指23.38个百分点。经统计,张顺平通过“账户组2”交易“中马传动”盈利5,570,203.06元。综上,2017年6月26日至2018年4月27日期间,张顺平控制使用“账户组1”和“账户组2”操纵“维格娜丝”等11只股票,合计盈利20,850,067.90元。上述违法事实,有相关人员询问笔录、证券账户资料及情况说明、交易流水、证券账户交易终端信息、银行账户资料、证券交易所统计数据等证据证明,足以认定。张顺平的上述行为违反了2005年《证券法》第七十七条第一款第一项、第三项和第四项的规定,构成2005年《证券法》第二百零三条所述的操纵证券市场行为。根据当事人违法行为的事实、性质、情节与社会危害程度,依据2005年《证券法》第二百零三条的规定,我会决定:责令张顺平依法处理非法持有的证券,没收违法所得20,850,067.90元,并处以62,550,203.70元罚款。上述当事人应自收到本处罚决定书之日起15日内,将罚没款汇交中国证券监督管理委员会开户银行:中信银行北京分行营业部,账号:7111010189800000162,由该行直接上缴国库,并将注有当事人名称的付款凭证复印件送中国证券监督管理委员会行政处罚委员会办公室备案。当事人如果对本处罚决定不服,可在收到本处罚决定书之日起60日内向中国证券监督管理委员会申请行政复议,也可在收到本处罚决定书之日起6个月内直接向有管辖权的人民法院提起行政诉讼。复议和诉讼期间,上述决定不停止执行。中国证监会2024年1月15日 | D1: 45306
A2: 是 | B2: 是 | C2: 〔2023〕83号当事人:陈磊,男,1970年3月出生,深圳市君如资产管理顾问有限公司(以下简称君如资产)董事长,住址:广东省深圳市罗湖区。吴限,男,1968年5月出生,深圳市劲拓自动化设备股份有限公司(以下简称劲拓股份)实际控制人,时任劲拓股份董事长。住址:广东省深圳市南山区。林建武,男,1974年9月出生,深圳市汇海宏融投资发展有限公司(以下简称汇海宏融)董事长,住址:广东省深圳市宝安区。依据2005年修订的《中华人民共和国证券法》(以下简称2005年《证券法》)有关规定,我会依法对陈磊、吴限、林建武等操纵劲拓股份股票价格进行了立案调查、审理,并依法向当事人告知了做出行政处罚的事实、理由、依据以及当事人依法享有的权利。根据当事人陈磊、林建武、吴限的要求,我会举行了听证,听取了当事人的陈述和申辩。本案现已调查、审理终结。经查明,陈磊、吴限、林建武存在以下违法事实:一、陈磊、林建武、吴限筹划、商议劲拓股份市值管理2017年6月,君如资产执行董事陈磊要求君如资产员工制作劲拓股份市值管理方案,拟联系劲拓股份大股东合作进行市值管理。汇海宏融董事长林建武与劲拓股份董事长及实际控制人吴限为朋友关系,两人均为长江商学院校友。2017年7月下旬至8月初,陈磊与林建武就劲拓股份市值管理及双方合作事宜多次沟通,并签订协议,约定由林建武帮助君如资产与吴限达成劲拓股份市值管理合作,陈磊则承诺将相关收益分配给林建武作为回报。在此期间,经由林建武居间,陈磊顺利接洽劲拓股份大股东及实际控制人吴限,三方合作开展劲拓股份市值管理项目。2017年8月7日,君如资产员工将劲拓股份市值管理项目进展状态更新为“完成签约,募集资金中”。之后,劲拓股份市值管理合作项目进入实质性操作阶段。二、当事人控制使用账户情况陈磊、林建武和吴限三方紧密合作,为实施市值管理筹集资金、准备账户。其中,吴限筹资以他人名义认购华宝信托有限责任公司-“辉煌”184号单一资金信托(以下简称“辉煌184号”)、陕西国际信托股份有限公司-陕国投·金元宝31号证券投资集合资金信托计划(以下简称“金元宝31号”)B类份额,通过1比2配资成立信托计划,将产品账户交由投资顾问君如资产具体操作。陈磊通过君如资产、深圳市前海小龙资产管理有限公司(以下简称前海小龙)、玖盈资本管理(深圳)有限责任公司(以下简称玖盈资本)等平台,发起设立数只私募基金产品,筹集大量资金,主要用于交易“劲拓股份”等由君如资产负责市值管理的股票。林建武亦参与了相关资金与账户的筹集活动。同时,陈磊、林建武、吴限等还使用多个自然人证券账户交易“劲拓股份”。陈磊、林建武、吴限控制账户(以下简称账户组)具体如下:1.陈磊控制使用23个账户根据账户资金来源、相关当事人之间关于账户设立和使用的信息交流、PB系统具体使用情况、交易终端关联及相关当事人询问笔录等证据,陈磊实际控制使用“辉煌184号”等23个账户,涉及28个证券账号:“辉煌184号”账户,2017年10月18日于华林证券深圳龙华证券营业部开立资金账户,下挂深圳证券账户089****074。“金元宝31号”账户,2017年12月5日于中信证券广东分公司开立资金账户,下挂深圳证券账户089****568。“兴业期货-进取1号集合资产管理计划”(以下简称“兴业进取1号”)账户,2017年12月26日于中信证券上海东方路证券营业部开立资金账户,下挂深圳证券账户089****307。“深圳市君如资产管理顾问有限公司-君如价值1号私募证券投资基金”(以下简称“君如价值1号”)账户,2018年3月12日于江海证券深圳民田路证券营业部开立信用资金账户,下挂深圳信用证券账户068***981。“深圳市君如资产管理顾问有限公司-君如价值2号私募证券投资基金”(以下简称“君如价值2号”)账户,2018年3月12日于江海证券深圳民田路营业部开立信用资金账户,下挂深圳信用证券账户068****982。“深圳市君如资产管理顾问有限公司-君如精选5号私募证券投资基金”(以下简称“君如精选5号”)账户,2018年6月6日于光大证券深圳新园路证券营业部开立资金账户,下挂深圳证券账户089***874。“深圳市君如资产管理顾问有限公司-君如精选6号私募证券投资基金”(以下简称“君如精选6号”)账户,2019年1月23日于华创证券凯里文化北路证券营业部开立信用资金账户,下挂深圳信用证券账户068***907。“深圳市君如资产管理顾问有限公司-赢丰成长1号私募基金”(以下简称“君如赢丰1号”)账户,2017年12月6日于华林证券深圳龙华证券营业部开立信用资金账户,下挂深圳信用证券账户068***449。“深圳市君如资产管理顾问有限公司-创智1号私募基金”(以下简称“君如创智1号”)账户,2018年1月24日于华林证券深圳龙华证券营业部开立信用资金账户,下挂深圳信用证券账户068***324。“深圳市前海小龙资产管理有限公司-小龙趋势1号私募证券投资基金”(以下简称“小龙趋势1号”)账户,2018年8月30日于光大证券深圳新园路营业部开立普通资金账户,下挂深圳证券账户089***458,2018年8月31日开立信用资金账户,下挂深圳信用证券账户068***005。“玖盈资本管理(深圳)有限责任公司-玖盈一号私募证券投资基金”(以下简称“玖盈一号”)账户,2018年12月18日于国泰君安证券深圳益田路营业部开立资金账户,下挂深圳证券账户089***207,2018年12月25日开立信用资金账户,下挂深圳信用证券账户068***579。“玖盈资本管理(深圳)有限责任公司-玖盈二号私募证券投资基金”(以下简称“玖盈二号”)账户,2019年1月24日于东兴证券福州五四路证券营业部开立资金账户,下挂深圳证券账户089****317,2019年1月29日开立信用资金账户,下挂深圳信用证券账户068***977。“玖盈资本管理(深圳)有限责任公司-玖盈三号私募证券投资基金”(以下简称“玖盈三号”)账户,2019年1月8日于国泰君安证券深圳益田路营业部开立资金账户,下挂深圳证券账户089****418、深圳信用证券账户068****764。“孙某梅”账户,2017年12月12日于中泰证券济南英雄山路证券营业部开立信用资金账户,下挂深圳信用证券账户060****198。“孙某瑞”账户,2017年8月21日于中泰证券济南英雄山路证券营业部开立信用资金账户,下挂深圳信用证券账户060****066。“张某波”账户,2018年1月19日中泰证券济南英雄山路证券营业部开立信用资金账户,下挂深圳信用证券账户060****204。“姚某刚”账户,2015年2月17日于中泰证券济南英雄山路证券营业部开立信用资金账户,下挂深圳信用证券账户060****231。“刘某香”账户,2018年3月21日于中泰证券济南英雄山路证券营业部开立信用资金账户,下挂深圳信用证券账户060****888。“郭某增”账户,2018年8月27日于中泰证券股份有限公司济南英雄山路证券营业部开立资金账户,下挂深圳证券账户025****652,2018年8月30日开立信用资金账户,下挂深圳信用证券账户060****160。“孙某民”账户,2018年4月20日于银河证券深圳深业上城证券营业部开立信用资金账户,下挂深圳信用证券账户060****854。“姬某华”账户,2018年5月15日于新时代证券深圳科苑路证券营业部开立信用资金账户,下挂深圳信用证券账户060****093。“罗某1”账户,2018年1月19日于华林证券深圳龙华营业部开立信用资金账户,下挂深圳信用证券账户060****792。该账户资金来源于吴限,由林建武提供给陈磊使用。“傅某斌”账户,2015年12月7日在西部证券深圳分公司营销业务部开立资金账户,下挂深圳证券账户005****110。2018年10月18日至2018年12月25日,吴限向其同学借用“傅某斌”账户,交由陈磊操作。2.林建武控制使用6个账户根据账户资金来源、相关当事人之间关于账户设立和使用的信息交流、交易终端关联及相关当事人询问笔录等证据,林建武控制使用“林某芬”等6个账户,涉及10个证券账号。具体如下:“林某芬”账户,2015年7月15日于平安证券芜湖营业部开立资金账户,下挂深圳证券账户018****213;2018年4月9日于平安证券芜湖营业部开立信用账户,下挂深圳信用证券账户060****493;2018年7月9日于华林证券深圳龙华营业部开立资金账户,下挂深圳证券账户018****213。“罗某2”账户,2018年1月23日于华林证券深圳龙华营业部开立信用资金账户,下挂深圳信用证券账户0604857521;2018年9月20日于平安证券深圳蛇口营业部开立资金账户,下挂深圳证券账户019****853。“黄某合”账户,2018年9月25日于平安证券深圳蛇口营业部开立信用资金账户,下挂深圳信用证券账户060****506。“刘某婷”账户,2016年11月2日于华林证券深圳龙华营业部开立资金账户,下挂深圳证券账户021****091;2017年6月12日开立信用资金账户,下挂深圳信用证券账户060****790。2019年1月11日、1月21日在平安证券深圳金田路证券营业部开立资金账户、信用资金账户,下挂深圳证券账户021****091、深圳信用证券账户060****790。“陈某如”账户,2018年1月23日于华林证券深圳龙华营业部开立资金账户,下挂深圳证券账户024****588,2018年1月25日开立信用资金账户,下挂深圳信用证券账户060****905。“林某森”账户,2018年7月26日于平安证券深圳金田路证券营业部开立信用资金账户,下挂深圳信用证券账户060****414。3.吴限控制使用7个账户根据账户资金来源、交易终端关联、相关当事人手机数据、询问笔录、书面协议等证据,吴限控制使用“吴限”等7个账户,具体如下:“吴限”账户,2018年6月27日于招商证券厦门湖滨东路营业部开立资金账户,下挂深圳证券账户010****477。“邓某”账户,2018年12月18日于财通证券成都天泰路营业部开立资金账户,下挂深圳证券账户025****223。“涂某娜”账户,2010年4月23日于光大证券深圳深南大道营业部开立资金账户,下挂深圳证券账户013****171。“孙某聚”账户,2014年10月13日于兴业证券深圳侨香路证券营业部开立资金账户,下挂深圳证券账户015****659。“朱某陵”账户,2016年11月14日于招商证券福清江滨路营业部开立资金账户,下挂深圳证券账户005****202。“余某盛”账户,2019年3月6日于国信证券深圳福中分公司开立资金账户,下挂深圳证券账户026****876。“劲通电子”账户,2015年11月24日于招商证券深圳蛇口工业三路营业部开立资金账户,下挂深圳证券账户080****428。三、陈磊、吴限、林建武利用资金、持股优势和信息优势操纵“劲拓股份”2017年11月6日至2019年4月29日(以下简称操纵期间),陈磊、吴限、林建武控制使用涉案账户组,通过集中资金优势、持股优势连续买卖,在实际控制的账户之间交易,以及利用信息优势影响股价等方式,操纵“劲拓股份”交易价格。期间,“劲拓股份”股价上涨19.93%,同期创业板综指下跌18.55%,偏离38.48个百分点。经计算,陈磊、吴限、林建武操纵行为获利165,262,585.59元。1.集中资金优势、持股优势连续买卖操纵期间的361个交易日中,账户组持有“劲拓股份”流通股占公司流通股比例的日均值为23.41%,其中账户组持股占流通股比例在10%以上的有344天,在20%以上的有174天,在30%以上的有137天。期间,账户组当日申买“劲拓股份”笔数在2笔以上的交易天数为260天,其中申买排名第一的天数为179天。账户组申买量占市场申买量比例在10%以上的有152天,在20%以上的有78天。操纵期间,账户组竞价成交量(不含账户组内彼此成交的数量)占市场竞价成交量的比例在10%以上的有166天,在20%以上的有42天,最高占比达33.82%。其中,账户组竞价买入成交量(不含账户组内彼此成交的数量)占市场竞价买成交量比例在10%以上的天数为160天,占比在20%以上的天数为93天,最高占比达67.25%。2.在自己实际控制的账户之间进行证券交易操纵期间,陈磊、林建武等人共计有137个交易日在实际控制的账户之间交易“劲拓股份”,交易量合计2402万余股,占账户组竞价买/卖成交量比例约为20%。期间,其在实际控制的账户之间的交易量占市场竞价成交量超过10%的有27天,最高占比达35.83%。3.利用信息优势影响股价陈磊、吴限等人利用信息优势地位,通过密集发布利好公告,联系证券分析师配合发布研究报告,以及组织员工在股吧发贴等方式,拉抬“劲拓股份”股价。2019年1月10日至2019年4月29日的72个交易日内,劲拓股份密集发布利好公告,其中涉及股份回购公告7份,5%以上股东君如资产旗下基金增持公告1份,2018年度业绩预增公告2份,中标及销售合同公告各1份,以及接受机构调研11次。同时,吴限授意公司人员联系兴业证券等机构的分析师,配合上市公司的利好公告频繁发布关键事项点评、深度报告等,吸引投资者买入“劲拓股份”。陈磊则指使属下员工在东方财富网的“劲拓股份”股吧发帖、评论,诱导投资者买入。2019年1月10日至2019年4月29日,“劲拓股份”股价从14.85元/股涨到19.92元/股,上涨34.14%。期间,“劲拓股份”在2019年4月4日收盘价达25.19元/股,相比期初上涨69.63%。以上事实,有相关证券账户资料、银行账户资料、相关人员询问笔录、电子设备取证信息、交易所相关数据等证据证明,足以认定。我会认为,陈磊、林建武、吴限的上述行为,违反了2005年《证券法》第七十七条第一款第一项、第三项、第四项的规定,构成第二百零三条所述的操纵证券市场行为。听证过程中,当事人陈磊、林建武、吴限提出了以下申辩意见:陈磊在申辩意见中提出:第一,陈磊从未主动牵头劲拓股份市值管理,并未与吴限签署过市值管理协议或相关文件,也没有其他证据证明吴陈二人合谋操纵劲拓股份股票。陈磊是在接触林建武、吴限后,再让员工从网上摘抄所谓的市值管理投资协议,微信记录上最早出现的“JTGF”市值管理方案计划书的时间是在陈磊与另两名当事人见面之后。再者,告知书中的“谋划由君如资产牵头,联合券商、基金、信托、私募、牛散等合作单位一起协力,对劲拓股份进行市值管理”的表述并未在陈磊发出的市值管理方案中出现过。调查人员称包含该内容的方案来源于君如资产员工王某发送给陈磊的文件,但陈磊并未向他人发送过该方案。第二,除君如资产管理的产品外,陈磊未控制其他账户。一是陈磊未控制玖盈资本、前海小龙公司,亦未控制玖盈系列账户和小龙趋势1号账户。二是陈磊未控制“罗某1”“傅某斌”“兴业进取1号”账户。三是陈磊虽与“姚某刚”“刘某香”“张某波”“孙某梅”“孙某瑞”账户签订过投资合作协议,但仅是给予投资建议,未实际控制、操作上述账户。四是陈磊未控制“郭某增”“姬某华”“孙某民”账户。第三,陈磊未实施操纵证券市场行为。一是其管理的君如系列产品账户交易“劲拓股份”合法合规,在举牌成为劲拓股份的正式股东后,及时按规定披露基金资金持股情况,不存在利用资金优势和持股优势操纵的行为。陈磊还积极和劲拓股份管理层沟通,为公司管理层出谋划策如建议利用国务院新规积极回购公司股票等,并积极介绍对接各种业务,尽一个股东的责任和义务。二是“劲拓股份”上涨集中于2019年2月至4月,期间股价从13.56元上涨至最高25.7元,陈磊管理的产品账户没有参与“劲拓股份”的拉抬和出货行为。三是东方财富网“股吧”是公众讨论平台,可以自由发表言论,在“股吧”发帖不足以影响股价。第四,本案责任划分偏颇、违法所得认定错误。一是陈磊不是市值管理的发起人,也不具有决定权。只有吴限作为上市公司实际控制人,才对此有拍板决定的权利。二是陈磊及君如资产没有向告知书所列账户出过资,而吴限及林建武有大量出资,其中“辉煌184号”由吴限通过傅某斌出资5000万并配资1亿,账户获利1700余万全部返还至傅某斌;“金元宝31号”由吴限通过王熙光出资2500万并配资5000万;“君如赢丰1号”由林建武通过徐某雄出资5000万并配资5000万;“君如创智1号”由林建武通过李某中出资5000万并配资5000万。三是陈磊不是最大受益人。陈磊的获利最多是收益分成、通道费用、返佣等,而吴限及林建武的配偶在案涉期间有大规模卖出。四是即使认定存在操纵市场,也应当扣除非陈磊控制的相关账户,并依照陈磊实际获利而非账户获利金额计算违法所得。第五,本案中,吴限、林建武作为上市公司大股东、实际控制人,具有信息优势,众多涉案的私募产品也由其安排、出资,相比之下陈磊作为一个私募管理人根本无法起到关键作用。因此,即便本案构成操纵证券市场,陈磊的涉案行为也属于显著轻微,不应给予市场禁入。吴限在申辩意见中提出:第一,吴限不存在与陈磊、林建武合谋操纵的主观意图。一是劲拓股份经营良好,吴限本人没有债务压力,吴限不存在与陈磊等人合谋操纵股价的动机。在告知书认定的操纵期间特别是“劲拓股份”价格上涨时期,吴限并未卖出其持有的股票获利。本案违法所得也没有一分钱流向吴限控制的账户。二是陈磊与林建武合谋以“市值管理”为名欺骗吴限,吴限对陈磊与林建武签订的居间协议不知情,也未与二人达成操纵“劲拓股份”合意。本案中,陈磊打着“市值管理”的幌子通过林建武认识了吴限并向其介绍市值管理,林建武为了促成所谓的市值管理,不惜亲自指导陈磊如何修改协议,并最终说服申辩人吴限参与市值管理。而吴限自始至终处在被蒙蔽的状态,只是按照陈磊和林建武的要求出资,并找他人帮忙,但这些都是基于吴限对合作市值管理的理解,而绝非合谋操纵劲拓股份股价。三是吴限拟引入陈磊控制的君如资产为战略投资者,但未向其泄露公司内部信息,更没有与其合谋操纵自己公司的股票。2019年1月左右,吴限了解到公司员工还在向君如资产提供股东名册后,就明令禁止再向君如资产提供股东名册。第二,吴限不存在利用资金优势、持股优势连续买卖的行为。一是吴限未安排以他人名义认购“辉煌184号”“金元宝31号”产品,前述产品的实际出资人分别应为徐某、王某光。二是“朱某陵”“劲通电子”账户并非由吴限控制。三是吴限对“邓某”“涂某娜”“孙某聚”“余某盛”账户的控制并非为了操纵证券市场,而是发现被骗后的自保、自救行为。2018年11月吴限与林建武、陈磊的关系破裂,因此在2018年12月至2019年3月期间采取以票还钱的方式进行了切割,将吴限先期投入资金所买入的股票,以及委托林建武的亲戚林某芬代持的股票平移到“邓某”“涂某娜”“孙某聚”“余某盛”等账户。第三,吴限不存在利用信息优势影响股价的行为。劲拓股份在2019年1月10日至4月29日发布的证监会认定的21份利好公告均是按照证监会、深圳证券交易所的规定,按期发布,吴限不存在控制公告发布节奏影响股价的情形。一是启动股份回购的原因是,2018年底韩国政府封锁柔性屏的相关设备,国内相应的生产厂商都以较高的薪资挖走劲拓股份的核心骨干人员,公司正努力突破柔性屏的关键技术,为此不得不通过股权激励稳定技术人才。将回购金额下限由5000万元调高至1亿元,是经过公司管理层内部讨论的结果,目的是为了更大规模地施行股权激励计划。且公司在2018年底的货币资金余额为5885.01万元,银行理财资金余额16,703万元,银行授信额度24500万元,公司合计可支配资金约为41179.18万元。此外2018年公司经营活动现金流净额12210.47万元。劲拓股份在12个月内的时间内有足够的能力和资金进行股份回购。至于劲拓股份公司董秘及相关人员与君如资产员工余某宏建立微信聊天群,并在国泰君安开立回购账户以及君如资产员工向公司证券事务代表建议回购时间安排、打听回购进度等,吴限并不知情,也不可能管理到如此细节的工作内容。二是2019年2月14日发布的君发资产增持公告属于按照监管规定及时发布的公告。君如资产作为市场上并不知名的私募机构,增持1%的消息也不属于重大利好,且公告后股价有大幅下跌。三是从2019年1月10日至4月29日,劲拓股份除了发布2份2018年度业绩预增公告,还在3月8日发布了2019年一季度业绩预亏公告。由于劲拓股份股价主要在3月至4月上涨,此时公告扭盈为亏,反而会打压市场。四是关于机构调研公告,是因为机构投资者对于劲拓股份是否生产3D贴合设备以及进展比较关注,在2019年2月19日起密集地来劲拓股份进行调研。劲拓股份公告机构调研符合规定,且吴限也无法控制机构来劲拓股份调研的时间。五是2019年4月11日中标公告是根据《中标通知书》及时发布,其公告的中标金额8120万元与4月26日公告的合同金额5424万元存在差异,是采购方根据生产需要自主决定的,为了维护和大客户的关系,劲拓股份及吴限只能配合采购方调整合同总价。六是吴限不存在授意相关人员联系分析师的情形,告知书事实认定错误,缺乏证据支持。第四,违法所得计算错误。一是吴限在2018年11月起即不再相信陈磊和君如资产作为战略投资者身份,并且已经不再向君如资产、陈磊提供股东名册,以2019年4月29日为共同操纵期间截止日明显缺乏事实和法律依据。二是告知书认定的账户组之间相互转让劲拓股份股票的获利不应当计算成违法所得。三是计算方式中卖出金额按照给交易所的发函日2020年9月10日计算,余股市值按照操纵截止日2019年4月29日的收盘价计算,导致获利的重复计算。四是“邓某”证券账户、“孙某聚”证券账户系吴限平移股票使用的账户,且主要是通过大宗交易的方式进行股票交易,其盈利不应当作为非法所得。第五,责任划分错误,违反罪行相当原则。吴限并不知晓,也不可能知晓陈磊、林建武还涉嫌控制其他个人账户交易劲拓股份的股票。陈磊、林建武涉嫌控制的个人账户的“获利”让吴限来承担明显缺乏法律依据。吴限的行为与本案陈磊的主导性和林建武的居间及私下参与完全不同,让其承担40%的罚没严重违法了罪行相当的原则。林建武在申辩意见中提出:第一,林建武仅系市值管理居间人,所接触、了解的案涉市值管理不涉及任何操纵手段内容,不应基于申辩人参与居间,认定存在操纵市场的共同故意与共同行为。第二,告知书关于陈磊、林建武、吴限筹划、商议劲拓股份市值管理的事实认定无证据支持。一是2017年7月陈磊向林建武发送的《市值管理投资合作协议草案(劲拓股份)》并无“联合券商、基金、信托、私募、牛散等合作单位一起协力,对劲拓股份进行市值管理”的表述,也完全不涉及以非法手段、异常交易方式拉抬股价。二是林建武与陈磊、吴限各自对“市值管理项目”的理解、意图以及对自身角色的认识不同,根本没有形成“合作关系”,更谈不上“合作进行市值管理”。林建武直至听证会才知悉,陈磊所谓市值管理仅是他的“营销手段”。吴限前期也完全不知悉林建武是“市值管理居间人”。三是陈磊与吴限没有签署市值管理协议,君如资产员工的聊天记录及询问笔录只能证明陈磊与吴限见过面,但无法证明二人达成了“合作进行市值管理”的合意。第三,“刘某婷”“林某芬”等6个账户均由户主本人控制使用,账户盈亏与林建武无关,告知书关于林建武控制相关账户、为方案实施筹集资金、准备账户等事实认定错误,无证据支持。一是资金往来方面,林某森、罗某2、黄某合与林建武没有资金往来,其他账户虽有资金往来,但与交易劲拓股份股票无关。二是涉案账户交易决策都是户主使用自己的设备下单操作,终端符合其工作生活地点。第四,无证据证明“刘某婷”等6个账户存在连续交易及账户间交易等操纵行为。一是6个账户买卖“劲拓股份”的交易时点、策略、风格不一致,不存在“集中资金优势和持股优势连续交易股票”,交易劲拓股份股票也不异常。二是6个账户自身之间没有交易行为,其与陈磊、吴限相关账户可能存在被动成交,但不构成操纵情形。三是6个账户在劲拓股份股价大幅上涨之前,已经开始在不同时间点大量卖出,不符合股价高位精准卖出的特点。第五,对林建武违法所得的认定没有事实依据,适用法律错误,不能成立。一是在林建武完成居间工作后,陈磊为推诿支付居间费用,从未向林建武说明其控制账户组的设立及交易情况,在2018年10月左右,林建武与陈磊彻底决裂、断绝往来后,更不可能知悉、了解陈磊、吴限的账户组交易情况,因此林建武对于陈磊和吴限相关账户的交易情况完全不知情,更未从中获益。二是案涉6账户不是林建武的账户,也没有实施操纵行为,不应计算违法所得。三是“林某芬”账户的两笔大宗交易,是替林建武的配偶孔某和吴限代持,与涉案操纵行为无关,该部分大宗交易不应纳入违法所得计算。四是2019年1月10日至4月29日期间的“操纵”行为与林建武完全无关,6账户在此期间的卖出获利不属于违法所得。经复核,我会认为:首先,在案证据显示,陈磊、吴限、林建武具有操纵“劲拓股份”股价的故意。根据林建武、华林证券李某、吴限同学徐某等人询问笔录及相关微信聊天记录等证据,2017年7月至8月期间陈磊与林建武、吴限沟通的市值管理合作模式主要为,大股东与君如资产共同出资并通过配资成立信托计划,由君如资产通过二级市场操作拉升股价,并在上市公司业绩配合下实现公司市值大幅提升。同时,陈磊与林建武以《劲拓股份投资咨询合作协议》约定,林建武负责协助君如资产与劲拓股份的市值管理合作谈判成功,协助完成信托产品的设立和账户使用,并在合作期间提供或协助君如资产获取劲拓股份相关信息,而君如资产向其支付相应比例收益。且陈磊在林建武促成合作后向其出具《居间服务费支付承诺书》,称“鉴于林建武先生在本公司与劲拓股份市值管理项目合作的谈判中起到关键性作用,且协助我方完成若干信托计划及私募、资管产品的设立”,君如资产承诺将提取部分市值管理项目的业绩报酬及产品管理费,作为居间服务费支付给林建武。由此可见,2017年8月,在林建武的积极撮合下,陈磊与吴限就共同出资设立产品对劲拓股份进行市值管理达成合作。根据当事人微信交流内容、相关协议及相关人员陈述等,陈磊、吴限、林建武等当事人对其合作的本质为上市公司大股东与私募基金共同出资交易本公司股票,利用持股、资金及信息优势操纵股价,均有较明确认知。针对吴限提出其受他人蒙蔽、不知悉林建武与陈磊私下签订居间协议等申辩,我会认为,吴限作为上市公司董事长、实际控制人,在他人游说下同意与私募集基金合作,筹集资金、账户用于交易本公司股票,并配合提供股东名册等,其行为足以证明其操纵股价之意图。吴限对另两位当事人签订居间协议是否知情,并不影响对其操纵股价行为的认定。其次,当事人实施了操纵股价的相关行为。一是陈磊、吴限、林建武等人密切合作,为市值管理积极筹集资金、账户用于交易“劲拓股份”。根据吴限同学徐某、华林证券李某、黄某等人询问笔录及相关账户交易资料、银行流水等证据,陈磊控制的“辉煌184号”“金元宝31号”产品的B类份额资金实际来源于吴限,“罗某1”账户资金实际来源于吴限,由林建武提供给陈磊方操作。根据林建武询问笔录及相关人员陈述、相关账户交易资料、银行流水等证据,因吴限出资未达合作约定的2亿元,林建武本人提供几千万资金,通过借款给其下属李某中、徐某雄认购“君如创智1号”“君如赢丰1号”,借用老乡刘某婷、同学黄某合、亲戚林某芬等人账户等方式,增加交易“劲拓股份”资金规模。根据相关微信聊天记录、相关账户交易资料、银行流水及相关人员陈述等证据,陈磊不仅通过君如资产、前海小龙、玖盈资本等平台,发起设立数只私募基金产品用于交易“劲拓股份”,还通过证券投资合作方式向姚某刚借用“姚某刚”“孙某梅”等个人账户交易“劲拓股份”。关于账户控制关系,本案系根据相关人员指认、自认,涉案账户资金流转,交易终端关联,微信聊天记录中有关账户信息交流、投资合作协议文件等多项主客观证据综合作出认定,此外相关账户存在交易趋同、对倒等情形亦可印证当事人对涉案账户实际控制。我会对涉案账户控制关系的认定并无不当,对当事人的申辩不予采纳。二是陈磊、吴限、林建武通过集中资金优势、持股优势连续买卖,在实际控制的账户之间交易,以及利用信息优势影响股价等方式,操纵“劲拓股份”交易价格。关于集中资金、持股优势连续买卖。操纵期间的361个交易日中,当事人控制的账户组持有“劲拓股份”流通股占公司流通股比例的日均值为23.41%,占比最高为2018年10月18日,达37.35%。账户组竞价买入成交量(扣除对倒成交量)占市场竞价买成交量比例在10%以上的有160天,占比在20%以上的有93天,占比最高为2018年6月19日,达67.25%。关于在实际控制的账户之间交易。操纵期间,账户组内存在大量对倒成交,如:2017年12月20日,“劲通电子”账户共计卖出127.3万股,与“辉煌184号”“金元宝31号”“君如赢丰1号”三账户共计对倒成交79.41万股。2018年10月18日至19日,“傅某斌”账户共计买入212.17万股,与“辉煌184号”对倒成交113.63万股。2019年1月14日至15日,“孙某聚”账户共计卖出77.94万股,与“玖盈一号”“玖盈三号”两账户共计对倒成交28.53万股。关于利用信息优势影响股价。劲拓股份公司公告、兴业证券等券商研究报告、相关人员询问笔录、微信聊天记录等证据显示,在操纵后期即2019年1月10日至4月29日,陈磊、吴限等人通过密集发布利好公告、联系证券分析师配合发布研究报告及组织人员在股吧发贴等方式拉抬股价。期间,“劲拓股份”股价从14.85元/股涨到19.92元/股,上涨34.14%,其中2019年4月4日收盘价达25.19元/股,相比期初上涨69.63%。与此同时,账户组大量卖出,持有流通股总数由5776.71万股减至2780.12万股,持仓占公司流通股本比例由34.71%降至16.57%。针对陈磊、吴限辩称其未利用信息优势影响股价,我会认为其申辩不能成立。其一,陈磊作为君如资产的实际控制人,对君如资产增持“劲拓股份”及其信息披露有完全的主导权。君如资产于2019年2月14日披露其增持1%,并承诺六个月内不减持。当天股价上涨7%。结合陈磊指示员工在“股吧”发帖诱导投资者,同时涉案相关账户大量卖出等事实,足以认定其利用增持公告影响股价。其二,吴限作为劲拓股份董事长、实际控制人,足以左右上市公司的重大决策并对公司信息发布具有明显优势。相关信息披露形式上是否合规并非操纵与否的判定标准。其三,根据相关人员询问笔录及微信聊天记录等证据,以回购股份提振股价系陈磊提议,且君如资产员工还参与了劲拓股份回购账户开立事宜。以上事实表明陈磊、吴限等人共同谋划了回购事项。吴限提出的有关回购决策理由等申辩缺乏相应证据,其主张难以成立。综合以上事实,并结合吴限授意公司人员联系券商配合发布相关研报等行为,我会认定其利用信息优势影响股价并无不当。再次,本案对操纵违法所得认定并无不当。其一,本案中,陈磊、吴限、林建武基于共同的故意实施了操纵违法行为,我会在统计操纵指标与计算交易获利时,将其三人控制账户视为一个整体统一计算,符合共同操纵违法行为的认定逻辑与处理原则。当事人要求按各自控制使用账户分别计算违法所得的主张不能成立。其二,本案操纵盈利计算方法符合我会执法惯例,不存在当事人所称重复计算盈利问题。其三,关于当事人提出违法所得应剔除“林某芬”“邓某”“孙某聚”等账户大宗交易获利,我会认为,大宗交易虽不直接影响股价,但其作为当事人建仓手段之一,属于操纵行为的组成部分,不应将其同连续买卖、对倒交易等直接影响股价的操纵行为割裂开来。其四,关于当事人主张其于2018年10月决裂,其后的相关行为及获利均应分别认定与计算,我会认为,根据相关人员询问笔录及微信聊天记录等证据,上述主张与事实不符,不应采纳。最后,本案对当事人的量罚及责任比例分担并无不当。综合全案事实、证据,本案是私募基金实际控制人、上市公司实际控制人及居间人以市值管理合作为名,共同操纵上市公司股价的违法案件。其中,陈磊主动联络上市公司实际控制人,组织并具体实施操纵行为,包括控制多个产品与自然人账户通过连续买卖、对倒交易及发布增持公告等方式操纵股价;吴限作为上市公司董事长、实际控制人,与他人合谋操纵本公司股票,不仅提供部分账户和大量交易资金,还存在利用信息优势影响股价情形。陈磊、吴限在本案操纵违法行为中起主要作用,应承担主要责任。林建武明知陈磊存在操纵股价意图,为获取居间收益积极促成其与吴限的合作,并为市值管理筹集资金、账户,及帮助陈磊获取股东名册等,在本案操纵违法行为中起次要作用,应承担次要责任。我会在量罚时已综合考量本案违法行为性质、主客观情节等,并根据三位当事人在共同违法中的地位、作用确定责任比例,处理适当。综上,我会对当事人的申辩意见不予采纳。根据当事人违法行为的事实、性质、情节和社会危害程度,依据2005年《证券法》第二百零三条的规定,我会决定:对陈磊、吴限、林建武等人合谋操纵“劲拓股份”价格的行为没收违法所得共计165,262,585.59元,并处以495,787,756.76元的罚款,违法所得及罚款合计661,050,342.35元,由陈磊承担40%即264,420,136.94元,吴限承担40%即264,420,136.94元,林建武承担20%即132,210,068.47元。上述当事人应自收到本处罚决定之日起15日内,将罚款汇交中国证券监督管理委员会,开户银行:中信银行北京分行营业部,账号:7111010189800000162,由该行直接上缴国库,并将注有当事人名称的付款凭证复印件送中国证券监督管理委员会行政处罚委员会办公室备案。当事人如果对本处罚决定不服,可在收到本处罚决定书之日起60日内向中国证券监督管理委员会申请行政复议,也可在收到本处罚决定书之日起6个月内直接向有管辖权的人民法院提起行政诉讼。复议和诉讼期间,上述决定不停止执行。中国证监会2023年11月30日 | D2: 45260
A3: 是 | B3: 是 | C3: 〔2023〕40号当事人:俞国生,男,1957年10月出生,住址:浙江省杭州市下城区。张一苗,男,1982年11月出生,住址:浙江省杭州市下城区。依据2005年修订的《中华人民共和国证券法》(以下简称2005年《证券法》)的有关规定,我会对俞国生、张一苗操纵市场、超比例持股未披露及限制期交易行为进行了立案调查、审理,并依法向当事人告知了作出行政处罚的事实、理由、依据及当事人依法享有的权利,应当事人俞国生、张一苗的要求,2023年2月15日举行了听证会,听取了俞国生、张一苗及其代理人的陈述和申辩。本案现已调查、审理终结。经查明,俞国生、张一苗存在以下违法事实:一、俞国生、张一苗实际控制使用账户及交易情况俞国生系野风集团有限公司(以下简称野风集团)决策咨询委员会主任,浙江野风资产管理有限公司(以下简称野风资管)实际控制人,张一苗时任野风资管董事长,其为俞国生女婿。涉案期间,俞国生、张一苗以个人名义借入配资账户,并实际控制143个证券账户,交易“浙数文化”、“浙江交科”、“浙大网新”等。其中,俞国生、张一苗控制使用“童某青”等67个证券账户于2016年10月31日至2017年7月28日交易“浙数文化”,控制使用“童某青”等36个证券账户于2017年8月25日至2018年5月18日交易“浙江交科”,控制使用“童某青”等33个证券账户于2018年5月21日至2019年1月11日交易“浙江交科”,控制使用“童某青”等78个证券账户于2016年3月21日至2017年3月6日交易“浙大网新”。二、俞国生、张一苗操纵“浙数文化”情况(一)俞国生、张一苗控制使用“童某青”等67个证券账户情况2016年10月31日至2017年7月28日期间(以下简称操纵期间1),俞国生、张一苗以个人名义借入证券账户,并控制使用“童某青”“李某灵”“韩某挺”等67个证券账户(以下简称账户组1)交易“浙数文化”。(二)俞国生、张一苗控制账户组1实施操纵的总体情况和三个阶段操纵期间1共计145个交易日,俞国生、张一苗控制的账户组1期初无持股,其通过利用资金优势、持股优势连续买卖、在自己实际控制的账户之间进行交易等方式影响“浙数文化”交易价格和交易量,同时存在日内反向交易、盘中拉抬等手段,直至操纵期间1期末全部卖出“浙数文化”。操纵期间1内,俞国生、张一苗控制账户组1累计买入“浙数文化”201,502,203股,累计买入金额3,662,748,396元,累计卖出201,502,203股,累计卖出成交3,935,985,843元,盈利274,313,073.19元。根据交易行为、持仓变动及停牌等情况,俞国生、张一苗于操纵期间1内控制账户组1的操纵行为可分为建仓拉抬、震仓拉抬、减仓三个阶段:第一阶段为建仓拉抬阶段。自2016年10月31日起,账户组1集中买入“浙数文化”,并在2017年1月10日停牌前持续买入建仓。2016年10月31日至2017年1月9日,账户组1竞价买入“浙数文化”77,141,691股,竞价卖出“浙数文化”9,360,548股,净买入67,781,143股,由期初持股为0增加至期末持股67,781,143股,占总股本5.21%,占流通股5.70%。期间,“浙数文化”交易价格由每股14.31元上涨至最高19.21元,涨幅34.24%。第二阶段为震仓拉抬阶段。浙报数字文化集团股份有限公司(原浙报传媒集团股份有限公司,以下简称浙数文化)因筹划资产重组事项,于2017年1月10日至3月9日停牌。2017年3月10日复牌后,2017年3月10日至3月14日期间,“浙数文化”交易价格累计上涨5.91%,资产重组事项未显著影响“浙数文化”交易价格。2017年3月10日至6月16日,账户组1竞价买入成交“浙数文化”87,772,901股,竞价卖出成交80,233,639股,净买入7,539,262股,截至6月16日,账户组1持有“浙数文化”75,320,405股,占总股本比例为5.79%,占流通股的比例为6.34%。2017年3月10日至6月16日,账户组1连续交易“浙数文化”,维持“浙数文化”交易价格,同时继续增加买入,以在自己实际控制的账户之间进行交易、连续交易拉抬股价、日内反向交易等方式实施操纵。该期间内,“浙数文化”股票交易价格震荡明显,最高振幅21.31%,“浙数文化”股票交易价格从每股17.44元上涨至每股18.52元,涨幅6.19%。第三阶段为减仓阶段。2017年6月19日至7月28日,账户组1竞价买入成交“浙数文化”36,587,611股,竞价卖出成交“浙数文化”111,908,016股,净卖出“浙数文化”75,320,405股,期末无持股。减仓阶段,账户组1主要为卖出“浙数文化”,稳步减持“浙数文化”后大量卖出,直至全部卖出。该期间内,“浙数文化”交易价格从每股18.52元上涨至每股20.68元,涨幅11.66%。(三)俞国生、张一苗控制账户组1利用资金优势、持股优势连续买卖“浙数文化”1.资金优势账户组1在操纵期间1内对“浙数文化”的交易中具有明显资金优势。操纵期间1内的145个交易日中,账户组1有140个交易日存在竞价买入交易,合计买入成交366,274.83万元。其中,账户组1竞价买入成交金额超过2,500万元的有54个交易日,占账户组1竞价买入交易天数的38.57%;账户组1竞价买入成交金额超过4,000万元的有26个交易日,占账户组1竞价买入交易天数的18.57%。账户组1日均竞价买入成交金额为2,616.25万元,占市场平均日成交额的10.84%。其中,2016年10月31日,账户组1竞价买入“浙数文化”10,032,220股,成交金额高达15,278.99万元。2.持股优势操纵期间1内,账户组1利用资金优势大量买入进而形成持股优势,持有“浙数文化”超过流通股本比例5%的交易日为96天,占操纵期间1内全部交易日的66.2%。其中,2017年4月27日,账户组1持有“浙数文化”占流通股本比例达到最高值7.94%。3.连续交易关于申买量排名指标。在操纵期间1内的145个交易日中,账户组有144个交易日交易了“浙数文化”,占比99.31%。其中有93个交易日,账户组1的申买量排名第一,占比为64.58%;有138个交易日,账户组1的申买量排名前十,占比为95.83%;有74个交易日,账户组1的申卖量排名第一,占比为51.39%;有111个交易日,账户组1的申卖量排名前十,占比为77.08%。关于竞价成交量指标。操纵期间1内,有79个交易日,账户组1的竞价成交量占比超过10%,占比为56.43%;有16个交易日,账户组1的竞价成交量占比超过20%,占比为11.11%。其中,2017年5月16日,账户组1的竞价成交量占比达到最高值,为27.08%。关于账户组1竞价买入及卖出成交量占市场竞价成交量指标。有86个交易日,账户组1竞价买入成交量占市场竞价成交量的比例超过10%,占比为59.72%;有23个交易日,该指标超过20%,占比为15.97%;有3个交易日,该指标超过30%,占比为2.08%。其中,2016年10月31日,账户组1竞价买入成交量占市场竞价成交量的比例达最高值,为43.07%。有70个交易日,账户组1竞价卖出成交量占市场竞价成交量的比例超过10%,占比为48.61%;有36个交易日,该指标超过20%,占比为25%。其中,2017年5月19日,账户组1竞价卖出成交量占市场竞价成交量的比例达最高值,为32.74%。关于申买价指标。操纵期间1内,账户组1申买价不低于市场卖一价的申买量为162,038,100股,占操纵期间1内账户组1连续竞价阶段总申买量230,839,700股的70.20%;账户组1申买价不低于卖一价且申报数量大于卖方一档数量的总申报量为141,835,500股,占操纵期间1内账户组1连续竞价阶段总申买量230,839,700股的61.44%;账户组1申买价不低于申买前最新市场成交价的申买量为175,858,200股,占操纵期间1内账户组1连续竞价阶段总申买量230,839,700股的76.18%;特别是2017年4月14日至7月19日期间内,账户组1申买价高于申买前最新市场成交价大于或等于1%的申买量为1,393,700股,占账户组期间连续竞价阶段总申买量23,436,800股的5.95%。上述指标说明账户组1在能以更低价格买到“浙数文化”的情形下,仍以高于市场价的价格申买,可见其影响“浙数文化”交易量和交易价格的意图明显。4.连续交易的典型拉抬区间操纵期间1内,在11个交易日中有12个时间段,账户组1多次盘中拉抬“浙数文化”交易价格,最高拉抬幅度达2.35%,并存在拉抬中及拉抬后反向卖出情形。典型拉抬区间如下:2017年3月13日,9:32:12至9:36:29期间,账户组1拉抬前一笔市场成交价为每股17.98元,该期间内,其最低申买价格为每股18.07元,最高申买价格为每股18.43元,申买均价为每股18.263元。该期间内,账户组1申报买入543,000股,申买占比29.35%,不低于卖一价申买量占账户组1总申买量的83.06%;主动买成交280,800股,占市场买成交量的比例为22.83%。账户组1在拉抬后反向卖出1,100,600股,卖出均价为每股18.57元。账户组1拉抬前一笔市场成交价为每股17.98元,该时段截止时市场成交价为18.43元,涨幅为2.35%。(四)俞国生、张一苗控制账户组1在自己实际控制的账户之间进行交易及日内反向交易在操纵期间1内的145个交易日中,有93个交易日存在账户组1的账户之间交易“浙数文化”的情况,占整个操纵期间1交易日天数的64.13%,占操纵期间1内账户组交易天数的64.58%。同时,有13个交易日存在账户组1的账户之间交易“浙数文化”成交量占当日市场竞价成交量的比例超过5%的情况,其中,2017年7月19日,账户组1的账户之间交易“浙数文化”成交量占当日市场竞价成交量的比例达到最高值7.76%。同时,操纵期间1内,账户组1有110个交易日存在日内反向交易,其中有70个交易日的反向交易成交量占账户组1成交量的比例超过50%。日均反向交易成交量占账户组1成交量比例为55.80%,最高达99.68%。(五)操纵期间1内,“浙数文化”股价走势偏离大盘指数及所在行业指数情况操纵期间1内,“浙数文化”股票交易价格出现较大波动。其中,2016年10月31日至2017年1月9日,“浙数文化”股票交易价格从14.31元/股上涨至17.44元/股,涨幅21.87%,与同期上证综指(上涨2.16%)相比偏离19.71个百分点,与出版指数(882463.WI,下跌2.75%)相比偏离24.62个百分点。2017年3月10日至6月16日,“浙数文化”股票交易价格从17.44元/股上涨至18.52元/股,涨幅6.19%,与同期上证综指(下跌1.52%)相比偏离7.71个百分点,与出版指数(882463.WI,下跌10.72%)相比偏离16.91个百分点。2017年6月19日至7月28日,“浙数文化”股票交易价格从18.52元/股上涨至20.68元/股,涨幅11.66%,与同期上证综指(上涨4.16%)相比偏离7.5个百分点,与出版指数(882463.WI,上涨2.17%)相比偏离9.49个百分点。综上,操纵期间1内,“浙数文化”股票交易价格走势与大盘面指数及所在行业指数出现较大背离。三、俞国生、张一苗于2017年8月25日至2018年5月18日操纵“浙江交科”情况(一)俞国生、张一苗控制使用“童某青”等36个证券账户情况2017年8月25日至2018年5月18日期间(以下简称操纵期间2),俞国生、张一苗以个人名义借入证券账户,并控制使用“童某青”“何某晨”“陈某夫”等36个证券账户(以下简称账户组2)交易“浙江交科”。(二)俞国生、张一苗控制账户组2实施操纵的总体情况和三个阶段操纵期间2共计170个交易日,俞国生、张一苗控制的账户组2期初无持股,其通过利用资金优势、持股优势连续买卖、在自己实际控制的账户之间进行交易等方式影响“浙江交科”交易价格和交易量,同时存在日内反向交易、盘中拉抬等手段,直至操纵期间2期末基本清空“浙江交科”。操纵期间2内,俞国生、张一苗控制账户组2累计买入“浙江交科”261,658,238股,累计买入金额3,663,333,011.57元,累计卖出253,337,359股,累计卖出成交3,678,886,536.46元,盈利102,545,916.82元。根据交易行为、持仓变动等情况,俞国生、张一苗于操纵期间2内控制账户组2的操纵行为可分为建仓拉抬、震仓拉抬、减仓三个阶段:第一阶段为建仓拉抬阶段。2017年8月25日至2017年11月3日,账户组2竞价买入“浙江交科”89,368,984股,竞价卖出17,446,217股,净买入71,922,767股,该期间期末持股71,922,767股,占总股本10.87%,占流通股15.87%。期间,“浙江交科”交易价格由每股10.75元上涨至每股14.00元,涨幅30.23%。第二阶段为震仓拉抬阶段。2017年11月6日至2018年1月10日,账户组2竞价买入“浙江交科”股票83,623,796股,竞价卖出102,856,015股,净卖出19,232,219股,该期间期末持股52,690,548股,占总股本4.04%,占流通股11.62%。期间,账户组2连续交易“浙江交科”,维持“浙江交科”交易价格,同时以在自己实际控制的账户之间进行交易、连续交易拉抬股价、日内反向交易等方式实施操纵。该期间内,“浙江交科”股票交易价格震荡明显,最高振幅18.79%。整个期间,“浙江交科”股票交易价格从每股14.00元上涨至每股16.00元,涨幅14.29%。第三阶段为减仓阶段。2018年1月11日至2018年5月18日,账户组竞价买入成交“浙江交科”股票88,665,458股,竞价卖出成交133,035,127股,净卖出44,369,669股,该期间期末持股8,320,879股。减仓阶段,账户组2主要为卖出“浙数文化”,交易活跃,同时以在自己实际控制的账户之间进行交易、连续交易拉抬股价、日内反向交易等方式实施操纵。账户组2在该期间内持有“浙数文化”股数逐渐下降,“浙江交科”交易价格从每股16.00元下跌至最低每股10.96元,跌幅31.50%。(三)俞国生、张一苗控制账户组2利用资金优势、持股优势连续买卖“浙江交科”1.资金优势账户组2在操纵期间2内对“浙江交科”的交易中具有明显资金优势。操纵期间2内的170个交易日中,账户组2有151个交易日存在竞价买入交易,合计买入成交366,333.3万元。其中,账户组2竞价买入金额超过1,500万元的有103个交易日,占账户组2竞价买入交易天数的68.21%;账户组2竞价买入成交金额超过3,000万元的有45个交易日,占账户组2竞价买入交易天数的29.80%;账户组2日均竞价买入成交金额为2,426.05万元,占市场平均日成交额的16.10%。其中,2017年8月31日,账户组2竞价买入“浙江交科”7,803,080股,成交金额9,440.80万元。2.持股优势操纵期间2内,账户组2利用资金优势大量买入进而形成持股优势,持有“浙江交科”超过流通股本比例5%的交易日为134天,占操纵期间2内全部交易日的78.82%;持有“浙江交科”超过流通股本比例10%的天数为75天,占操纵期间2内全部交易日的44.11%。其中,2017年11月3日,账户组2持有“浙江交科”占流通股本比例达到最高值15.87%。3.连续交易关于申买量排名指标。在操纵期间2内的170个交易日中,账户组2有162个交易日交易了“浙江交科”,占比95.29%。其中有106个交易日,账户组2的申买量排名第一,占比为65.43%;有150个交易日,账户组2的申买量排名前十,占比为92.59%;有135个交易日,账户组2的申卖量排名第一,占比为83.33%;有153个交易日,账户组2的申卖量排名前十,占比为94.44%。关于竞价成交量指标。操纵期间2内,有120个交易日,账户组2的竞价成交量占比超过10%,占比为74.07%;有56个交易日,账户组2的竞价成交量占比超过20%,占比为34.57%;有32个交易日,账户组2的竞价成交量占比超过30%,占比为19.75%。其中,2018年3月20日,账户组2的竞价成交量占比达到最高值,为48.58%。关于账户组2竞价买入及卖出成交量占市场竞价成交量指标。有108个交易日,账户组2竞价买入成交量占市场竞价成交量的比例超过10%,占比为66.67%;有59个交易日,该指标超过20%,占比为36.42%;有29个交易日,该指标超过30%,占比为17.9%。其中,2018年3月20日,账户组2竞价买入成交量占市场竞价成交量的比例达最高值,为48.13%。有106个交易日,账户组2竞价卖出成交量占市场竞价成交量的比例超过10%,占比为65.43%;有70个交易日,该指标超过20%,占比为43.21%;有37个交易日,该指标超过30%,占比为22.84%。其中,2018年3月28日,账户组2竞价卖出成交量占市场竞价成交量的比例达最高值,为50.93%。关于申买价指标。操纵期间2内,账户组2申买价不低于市场卖一价的申买量为230,051,900股,占操作期间2内账户组2连续竞价阶段总申买量296,834,900股的77.50%;账户组2申买价不低于卖一价且申报数量大于卖方一档数量的总申报量为207,325,200股,占操纵期间2内账户组2连续竞价阶段总申买量296,834,900股的69.85%;账户组2申买价不低于申买前最新市场成交价的申买量为244,545,700股,占操纵期间2内账户组2连续竞价阶段总申买量296,834,900股的82.38%;特别是2017年9月18日至2018年4月18日期间内,账户组2申买价高于申买前最新市场成交价大于或等于1%的申买量为2,714,000股,占账户组期间连续竞价阶段总申买量35,919,100股的7.56%。上述指标说明账户组2在能以更低价格买到“浙江交科”的情形下,仍以高于市场价的价格申买,可见其影响“浙江交科”交易量和交易价格的意图明显。4.连续交易的典型拉抬区间操纵期间2内,在77个交易日中有128个时间段,账户组2多次盘中拉抬“浙江交科”交易价格,最高拉抬幅度达3.37%,并存在拉抬中及拉抬后反向卖出情形。典型拉抬区间如下:2018年1月10日,9:34:30至10:04:36期间,账户组2拉抬前一笔市场成交价为每股16.21元,该期间内,其最低申买价格为每股16.23元,最高申买价格为每股16.83元,申买均价为每股16.56元。该期间内,账户组2申报买入3,698,400股,申买占比36.06%,不低于卖一价申买量占账户组2总申买量的61.62%;主动买成交1,281,064股,占市场买成交量的比例为33.02%。账户组2在拉抬后存在反向卖出,其中,拉抬中卖出1,369,400股,卖出均价为每股16.62元;拉抬后卖出2,199,300股,卖出均价为每股16.30元。账户组2拉抬前一笔市场成交价为每股16.21元,该时段截止时市场成交价为16.75元,涨幅为3.33%。(四)俞国生、张一苗控制账户组2在自己实际控制的账户之间进行交易及日内反向交易在操纵期间2内的170个交易日中,有121个交易日存在账户组2的账户之间交易“浙江交科”的情况,占整个操纵期间2交易日天数的71.17%。有49个交易日存在账户组2的账户之间交易“浙江交科”成交量占当日市场竞价成交量的比例超过5%的情况,有32个交易日存在账户组2的账户之间交易“浙江交科”成交量占当日市场竞价成交量的比例超过10%的情况,有4个交易日存在账户组2的账户之间交易“浙江交科”成交量占当日市场竞价成交量的比例超过20%的情况。其中,2018年3月20日,账户组2的账户之间交易“浙数文化”成交量占当日市场竞价成交量的比例达到最高值28.24%。同时,操纵期间2内,账户组2有137个交易日存在日内反向交易,其中有97个交易日的反向交易成交量占账户组2成交量的比例超过50%。日均反向交易成交量占账户组2成交量比例为66.99%,最高达99.34%。(五)操纵期间2内,“浙江交科”股价走势偏离大盘指数及所在行业指数情况操纵期间2内,“浙江交科”股票交易价格出现较大波动。其中,2017年8月25日至2017年11月3日,“浙江交科”股票交易价格从10.75元/股上涨至14.00元/股,涨幅30.23%,与同期中小板指(上涨8.85%)相比偏离21.38个百分点,与建筑指数(886016.WI,下跌1.68%)相比偏离31.91个百分点。2017年11月6日至2018年1月10日,“浙江交科”股票交易价格从14.00元/股上涨至16.00元/股,涨幅14.29%,与同期中小板指(下跌0.48%)相比偏离14.77个百分点,与建筑指数(886016.WI,下跌5.23%)相比偏离19.52个百分点。2018年1月11日至2018年5月18日,“浙江交科”股票交易价格从16.00元/股下跌至12.21元/股,跌幅23.69%,与同期中小板指(下跌6.83%)相比偏离16.86个百分点,与建筑指数(886016.WI,下跌12.85%)相比偏离10.84个百分点。综上,操纵期间2内,“浙江交科”股票交易价格走势与大盘指数及所在行业指数出现较大背离。四、俞国生、张一苗于2018年5月21日至2019年1月11日操纵“浙江交科”情况(一)俞国生、张一苗控制使用“童某青”等33个证券账户情况2018年5月21日至2019年1月11日期间(以下简称操纵期间3),俞国生、张一苗以个人名义借入证券账户,并控制使用“童某青”“张某”“邓某”等33个证券账户(以下简称账户组3)交易“浙江交科”。(二)俞国生、张一苗控制账户组3实施操纵的总体情况和三个阶段操纵期间3共计161个交易日,俞国生、张一苗控制的账户组3期初持有“浙江交科”8,320,879股,其通过利用资金优势、持股优势连续买卖、在自己实际控制的账户之间进行交易等方式影响“浙江交科”交易价格和交易量,同时存在日内反向交易、盘中拉抬等手段,直至操纵期间3期末全部卖出“浙江交科”。操纵期间3内,俞国生、张一苗控制账户组3累计买入“浙江交科”208,542,533股,累计买入金额2,171,351,363.81元,累计卖出216,863,412股,累计卖出成交2,303,834,342.46元,盈利36,451,611.14元。根据交易行为、持仓变动等情况,俞国生、张一苗于操纵期间3内控制账户组3的操纵行为可分为建仓、拉抬、减仓三个阶段:第一阶段为建仓阶段。2018年5月21日至10月16日,账户组3期初持股8,320,879股,该期间竞价买入“浙江交科”108,222,144股,竞价卖出64,893,359股,净买入43,328,785股,该期间期末持股51,649,664股,占总股本3.75%,占流通股9.23%。第二阶段为拉抬阶段。2018年10月17日至12月6日,账户组3竞价买入“浙江交科”股票63,979,952股,竞价卖出52,183,099股,净买入11,796,853股,该期间期末持股63,446,517股,占总股本4.61%,占流通股10.96%。期间,账户组3连续交易“浙江交科”,拉抬“浙江交科”交易价格,同时以在自己实际控制的账户之间进行交易、连续交易拉抬股价等方式实施操纵。该期间内,“浙江交科”股票交易价格大幅上涨。整个期间,“浙江交科”股票交易价格从每股7.25元上涨至每股11.26元,涨幅55.31%。第三阶段为减仓阶段。2018年12月7日至2019年1月11日,账户组竞价买入成交“浙江交科”股票36,340,437股,竞价卖出成交99,786,954股,净卖出63,446,517股,该期间期末无持股。减仓阶段,账户组3主要为卖出“浙数文化”,在该期间内持有“浙数文化”股数及比例大幅下降,“浙江交科”交易价格从每股11.26元下跌至每股8.78元,跌幅22.02%。(三)俞国生、张一苗控制账户组3利用资金优势、持股优势连续买卖“浙江交科”1.资金优势账户组3在操纵期间3内对“浙江交科”的交易中具有明显资金优势。操纵期间3内的161个交易日中,账户组3有153个交易日存在竞价买入交易,合计买入成交217,135.13万元。其中,账户组3竞价买入金额超过800万元的有101个交易日,占账户组3竞价买入交易天数的66.01%;账户组3竞价买入成交金额超过1,500万元的有59个交易日,占账户组3竞价买入交易天数的38.56%;账户组3日均竞价买入成交金额为1,419.18万元,占市场平均日成交额的17.88%。其中,2018年5月21日,账户组3竞价买入“浙江交科”4,130,805股,成交金额4,920.57万元。2.持股优势操纵期间3内,账户组3利用资金优势大量买入进而形成持股优势,持有“浙江交科”超过流通股本比例5%的交易日为106天,占操纵期间3内全部交易日的65.83%;持有“浙江交科”超过流通股本比例10%的天数为34天,占操纵期间3内全部交易日的21.11%。其中,2018年11月26日,账户组3持有“浙江交科”占流通股本比例达到最高值11.67%。3.连续交易关于申买量排名指标。在操纵期间3内的161个交易日中,账户组3有161个交易日交易了“浙江交科”,占比99.38%。其中有111个交易日,账户组3的申买量排名第一,占比为69.38%;有151个交易日,账户组3的申买量排名前十,占比为94.38%;有104个交易日,账户组3的申卖量排名第一,占比为65.00%;有140个交易日,账户组3的申卖量排名前十,占比为87.50%。关于竞价成交量指标。操纵期间3内,有113个交易日,账户组3的竞价成交量占比超过10%,占比为70.63%;有58个交易日,账户组3的竞价成交量占比超过20%,占比为36.25%;有22个交易日,账户组3的竞价成交量占比超过30%,占比为13.75%。其中,2018年12月19日,账户组3的竞价成交量占比达到最高值,为62.10%。关于账户组3竞价买入及卖出成交量占市场竞价成交量指标。有122个交易日,账户组3竞价买入成交量占市场竞价成交量的比例超过10%,占比为76.25%;有71个交易日,该指标超过20%,占比为44.38%;有29个交易日,该指标超过30%,占比为18.13%。其中,2018年11月15日,账户组3竞价买入成交量占市场竞价成交量的比例达最高值,为52.36%。有89个交易日,账户组3竞价卖出成交量占市场竞价成交量的比例超过10%,占比为55.63%;有52个交易日,该指标超过20%,占比为32.50%;有32个交易日,该指标超过30%,占比为20%。其中,2018年12月19日,账户组3竞价卖出成交量占市场竞价成交量的比例达最高值,为74.64%。关于申买价指标。操纵期间3内,账户组3申买价不低于市场卖一价的申买量为151,414,800股,占操作期间3内账户组3连续竞价阶段总申买量232,438,400股的65.14%;账户组3申买价不低于卖一价且申报数量大于卖方一档数量的总申报量为129,050,600股,占操纵期间3内账户组3连续竞价阶段总申买量232,438,400股的55.52%;账户组3申买价不低于申买前最新市场成交价的申买量为168,666,400股,占操纵期间3内账户组3连续竞价阶段总申买量232,438,400股的72.56%;特别是2018年6月7日至2019年1月7日期间内,账户组3申买价高于申买前最新市场成交价大于或等于1%的申买量为1,152,500股,占账户组期间连续竞价阶段总申买量34,301,000股的3.36%。上述指标说明账户组3在能以更低价格买到“浙江交科”的情形下,仍以高于市场价的价格申买,可见其影响“浙江交科”交易量和交易价格的意图明显。4.连续交易的典型拉抬区间操纵期间3内,在55个交易日中有94个时间段,账户组3多次盘中拉抬“浙江交科”交易价格,最高拉抬幅度达4.19%,并存在拉抬中及拉抬后反向卖出情形。典型拉抬区间如下:2018年11月26日,11:04:14至11:22:18期间,账户组3拉抬前一笔市场成交价为每股10.43元,该期间内,其最低申买价格为每股10.44元,最高申买价格为每股10.85元,申买均价为每股10.66元。该期间内,账户组3申报买入411,800股,申买占比45.59%,不低于卖一价申买量占账户组3总申买量的98.08%;账户组3买成交326,800股,占市场买成交量的比例为55.25%。账户组3在拉抬后存在反向卖出,其中,拉抬中卖出88,300股,卖出均价为每股10.72元;拉抬后卖出784,700股,卖出均价10.82元/股。账户组3拉抬前一笔市场成交价为每股10.43元,该时段截止时市场成交价为10.85元,涨幅为4.03%。(四)俞国生、张一苗控制账户组3在自己实际控制的账户之间进行交易及日内反向交易在操纵期间3内的161个交易日中,有121个交易日存在账户组3的账户之间交易“浙江交科”的情况,占整个操纵期间3交易日天数的75.15%。有52个交易日存在账户组3的账户之间交易“浙江交科”成交量占当日市场竞价成交量的比例超过5%的情况,有27个交易日存在账户组3的账户之间交易“浙江交科”成交量占当日市场竞价成交量的比例超过10%的情况,有7个交易日存在账户组3的账户之间交易“浙江交科”成交量占当日市场竞价成交量的比例超过20%的情况。其中,2018年12月19日,账户组3的账户之间交易“浙数文化”成交量占当日市场竞价成交量的比例达到最高值35.11%。同时,操纵期间3内,账户组3有136个交易日存在日内反向交易,其中有95个交易日的反向交易成交量占账户组3成交量的比例超过50%。日均反向交易成交量占账户组3成交量比例为65.28%,最高达99.10%。(五)操纵期间3内,“浙江交科”股价走势偏离大盘指数及所在行业指数情况操纵期间3内,“浙江交科”股票交易价格出现较大波动。其中,2018年5月21日至10月16日,“浙江交科”股票交易价格从每股12.21元下跌至每股7.25元,跌幅40.62%,与同期中小板指(下跌32.84%)相比偏离7.78个百分点,与建筑指数(886016.WI,下跌19.42%)相比偏离21.20个百分点。2018年10月17日至12月6日,股价从每股7.25元上涨至每股11.26元,涨幅55.31%,与同期中小板指(上涨4.10%)相比偏离51.21个百分点,与建筑指数(886016.WI,上涨5.24%)相比偏离50.07个百分点。2018年12月7日至2019年1月11日,股价从每股11.26元下跌至每股8.78元,跌幅22.02%,与同期中小板指(下跌5.24%)相比偏离16.78个百分点,与建筑指数(886016.WI,下跌1.56%)相比偏离20.46个百分点。综上,操纵期间3内,“浙江交科”股票交易价格走势与大盘指数及所在行业指数出现较大背离。五、俞国生、张一苗超比例持有“浙大网新”未披露及限制期内交易“浙大网新”(一)俞国生、张一苗控制使用“童某青”等78个账户情况2016年3月21日至2017年3月6日(以下简称交易期间),俞国生、张一苗控制使用“童某青”“姜某冬”“杨某”等78个证券账户(以下简称账户组4)交易“浙大网新”。(二)超比例持有“浙大网新”未披露的情况2016年3月21日至2017年3月6日期间,俞国生、张一苗控制“童某青”等78个证券账户连续交易“浙大网新”。2016年3月21日,账户组4在交易期间期初未持有“浙大网新”。截至2016年4月15日,账户组4持有“浙大网新”42,482,296股,占上市公司已发行股份的比例达到4.65%。截至2016年4月18日,账户组4持有“浙大网新”48,053,596股,占上市公司已发行股份的比例达到5.26%,首次达到上市公司已发行股份的5%。截至2016年7月12日,账户组4持有“浙大网新”92,459,435股,占上市公司已发行股份的比例达到10.12%。截至2016年7月13日,账户组4持有“浙大网新”98,312,735股,占上市公司已发行股份的比例达到10.76%。截至2016年8月11日,账户组4持有“浙大网新”118,809,976股,占上市公司已发行股份的比例达到13%,为涉案期间内的最高值。截至2016年10月26日,账户组4持有“浙大网新”43,767,216股,占上市公司已发行股份的比例达到4.79%。截至2017年3月6日,账户组4未持有“浙大网新”。俞国生、张一苗控制的账户组4持有“浙大网新”占上市公司已发行股份的比例达到5%后,未向国务院证券监督管理机构、证券交易所作书面报告,通知上市公司,并予公告。(三)限制期内交易情况2016年4月18日,俞国生、张一苗控制的账户组4持有“浙大网新”首次达到上市公司已发行股份的5%后未按规定履行报告及公告义务,并持续交易“浙大网新”,直至2017年3月6日全部卖出其持有的“浙大网新”。2016年4月19日至2017年3月6日期间内,账户组4累计买入“浙大网新”200,955,388股,买入金额为2,662,188,791.51元,累计卖出“浙大网新”249,008,984股,卖出金额为3,622,781,065元。上述违法事实,有相关人员询问笔录、银行流水、交易结算表、证券账户资料、交易所相关数据信息等证据证明,足以认定。俞国生、张一苗操纵“浙数文化”“浙江交科”的行为,违反2005年《证券法》第七十七条第一项、第三项的规定,构成2005年《证券法》第二百零三条所述的操纵证券市场行为。俞国生、张一苗在持股比例达到浙大网新科技股份有限公司(以下简称浙大网新)总股本的5%时,未按规定履行报告和信息披露义务,违反了2005年《证券法》第八十六条第一款规定,构成2005年《证券法》第一百九十三条第一款所述“发行人、上市公司或者其他信息披露义务人未按照规定披露信息”的信息披露违法行为。俞国生、张一苗限制期内交易“浙大网新”的行为,违反了2005年《证券法》第三十八条、第八十六条第一款规定,构成2005年《证券法》第二百零四条所述“违反法律规定,在限制转让期限内买卖证券”的违法行为。上述交易由俞国生负责总体决策,提供资金并承担交易产生的收益和亏损;张一苗负责具体决策并向交易员下达指令,安排相关人员通过其控制的银行账户向证券账户对应的存管银行账户进行转入保证金、支付利息、收取盈利等资金流转,同时向俞国生汇报,野风集团工作人员参与上述借入账户、划转资金和执行交易等过程。俞国生、张一苗及其代理人在听证及申辩材料中共同提出:其一,事先告知书认定张一苗与俞国生共同控制143个账户是错误的。两人之间仅存在借款关系,张一苗借入资金后的配资行为和借用配资账户交易股票行为均与俞国生无关,俞国生并未参与张一苗等人对资金的使用和决策,张一苗是自主交易决策,也未向俞国生汇报股票交易事项。其二,《结算表》《利息表》《备忘录》等文件(以下简称《结算表》等文件)与事实不符,不具备证据效力。联锦大厦23楼的办公室并非俞国生使用。俞国生称不知悉《结算表》等文件内容,且《结算表》等文件是假的。其三,部分证据不具有合法性,不符合证据标准。部分言辞证据存在相互矛盾的情形。关键性书证缺失,书证之间不能相互衔接,无法形成完整证据链条。其四,金某君、张某坤的交易与俞国生、张一苗无关。俞国生仅是将资金借给张一苗、金某君、张某坤等人,俞国生从未参与上述资金的具体使用和决策。金某君、张某坤相关交易系由其自行决策,金某君、张某坤的交易与俞国生、张一苗无关。此外,张一苗及其代理人在听证及申辩材料中还提出:其一,张一苗仅控制26个账户。张一苗与金某君、张某坤使用的证券账户无任何关系。张一苗控制的26个涉案账户交易“浙大网新”“浙数文化”“浙江交科”的情况并未达到事先告知书所述的数额和比例,不构成操纵市场、超比例持股未披露、限制期内交易等违法行为。其二,张一苗交易“浙数文化”“浙江交科”有充分合理的理由,没有操纵的主观故意,不构成操纵行为。张一苗通过调研、查阅公开信息等方式使用26个账户交易“浙大网新”“浙数文化”“浙江交科”,投资符合价值投资战略方向,与其以往偏向细分行业龙头的投资风格相符。张一苗委托章某铭操作时不涉及具体操作方式,由章某铭决定交易方式、价格、数量,故即使张一苗控制的账户存在违法情形,也不应由张一苗承担责任。综上,俞国生、张一苗请求免于处罚。经复核,我会认为:第一,关于账户控制关系。根据当事人自认、操盘方工作人员自认、配资方指认、第三方指认、《结算表》等文件、出资及配资协议、涉案账户组的资金来源及去向等在案证据,足以认定143个涉案账户由俞国生、张一苗共同控制,具体如下:1.根据在案证据,俞国生总体决策涉案账户组资金流转,获取盈利,涉案期间,相关账户累计向俞国生转出近3亿元,向野风集团转出近1亿元。涉案证券账户的资金来源和去向指向张一苗控制的账户,资金流转情况与张一苗、金某君关于以配资模式借用证券账户的陈述相符,张一苗控制账户的资金在违法行为发生前与俞国生、野风集团及其关联公司存在大额、频繁的资金往来。2.根据在案证据,张一苗在交易前后及中间阶段会向俞国生汇报,俞国生总体知悉所交易的股票情况,在资金划转、股票交易方面进行总体决策,起到核心作用。张一苗承认,交易“浙大网新”“浙数文化”“浙江交科”前,张一苗向俞国生汇报并征得俞国生同意。3.张一苗申辩称“我在调查中确实说过俞国生参与投资决策的话,但并非客观事实,是我在接受调查时临时编的”,同时张一苗申辩称金某君、张某坤系独立决策交易,该二人的交易与张一苗无关。我会认为,张一苗在调查阶段承认俞国生参与投资决策,并承认其通过金某君、张某坤借入配资账户,张一苗直接安排涉案银行账户的资金流转,具体决策证券交易,能够与本案其他证据相互印证。张一苗在陈述申辩材料和听证会上否认其在调查阶段的陈述,缺乏证据支持,我会依法不予采信。第二,关于《结算表》等文件的真实性。根据在案证据,杭州联锦大厦A幢23楼最大办公室是俞国生的办公室。调查人员在上述办公室取得《结算表》等文件,取证时俞国生秘书姚某晔在场,俞国生大女儿俞某签字确认“此文件取自俞国生位于联锦大厦A座23层办公室”。调查人员询问张一苗时,向张一苗出示《结算表》等文件,张一苗确认“此文件中涉及的证券账户是我借用的部分配资证券账户”。《结算表》等文件在制表、复核等过程经过数名野风集团员工签字审核,最终由张一苗签字并向俞国生汇报,且文件呈现的账户范围、统计期间、盈利情况与事先告知书认定事实基本相符。上述事实足以证明《结算表》等文件的真实性,当事人申辩称《结算表》等文件与事实不符没有相应证据支持,我会依法不予采信。第三,关于证据效力。调查程序符合法定程序要求,在案证据符合法定形式,主要违法事实有多方面证据相互印证,形成完整证据链,具备证据效力。我会对当事人相关申辩意见不予采纳。第四,关于金某君、张某坤是否独立交易决策的问题。在案证据足以证明金晓君、张建坤并非独立进行交易决策,而是由张一苗直接控制资金流转和交易决策。当事人所述部分账户由金某君、张某坤控制的说法与事实不符。具体如下:1.金某君承认其借入涉案配资账户,并交张一苗使用,金某君本人并未参与决策交易。张一苗承认其通过金某君、张某坤借入配资账户,并承认与张一苗所控制的银行账户相对应的证券账户都是其借用的。张一苗直接安排涉案银行账户的资金流转,具体决策证券交易。涉案账户组的相关交易呈现由同一主体控制的特征。同时,金某君、张某坤等人在野风集团任职并领取薪酬。2.《结算表》等文件涵盖与金某君、张某坤银行账户存在资金关联的证券账户。前已述及,《结算表》等文件由调查部门取自俞国生办公场所,由野风集团工作人员审核确认,最终由张一苗确认后向俞国生汇报,且张一苗承认《结算表》等文件涉及的证券账户是其借用的配资账户,该说法与金某君所述为张一苗借来配资账户的说法相互印证。故《结算表》等文件证明张一苗直接控制涉案账户组。第五,关于张一苗提出其控制26个涉案账户,基于价值投资原则从事交易的相关问题。如前所述,在案证据足以证明俞国生、张一苗共同控制涉案账户组,故张一苗所述其仅控制26个账户的申辩意见不予采纳。同时,根据在案证据,涉案账户组在涉案期间通过连续交易、在自己实际控制的账户内交易等手段,影响涉案股票价格和交易量,构成操纵市场违法行为。且张一苗询问笔录和交易痕迹显示,涉案账户组总体是每个账户匹配一台电脑,交易行为呈现相互配合、一致行动等特征,进一步说明当事人存在操纵的主观故意。对张一苗辩称相关交易不构成操纵行为等申辩意见,我会不予采纳。综上,我会对俞国生、张一苗及其代理人的申辩意见不予采纳。根据当事人违法行为的事实、性质、情节与社会危害程度,依据2005年《证券法》第一百九十三条第一款、第二百零三条、第二百零四条的规定,我会决定:一、对俞国生、张一苗操纵“浙数文化”行为,没收违法所得274,313,073.19元,并对俞国生、张一苗合计处以274,313,073.19元罚款,其中,对俞国生处以182,875,382.13元罚款,对张一苗处以91,437,691.06元罚款。二、对俞国生、张一苗于2017年8月25日至2018年5月18日操纵“浙江交科”行为,没收违法所得102,545,916.82元,并对俞国生、张一苗合计处以102,545,916.82元的罚款,其中,对俞国生处以68,363,944.55元罚款,对张一苗处以34,181,972.27元罚款。三、对俞国生、张一苗于2018年5月21日至2019年1月11日操纵“浙江交科”行为,没收违法所得36,451,611.14元,并对俞国生、张一苗合计处以36,451,611.14元的罚款,其中,对俞国生处以24,301,074.1元罚款,对张一苗处以12,150,537.04元罚款。四、对俞国生、张一苗超比例持有“浙大网新”未披露的行为,责令改正,给予警告,并处以30万元罚款,其中,对俞国生处以20万元罚款,对张一苗处以10万元罚款。五、对俞国生、张一苗限制期内交易“浙大网新”行为,责令改正,给予警告,并处以3,000万元罚款,其中,对俞国生处以2,000万元罚款,对张一苗处以1,000万元罚款。上述当事人应自收到本处罚决定书之日起15日内,将罚款汇交中国证券监督管理委员会开户银行:中信银行北京分行营业部,账号:7111010189800000162,由该行直接上缴国库,并将注有当事人名称的付款凭证复印件送中国证券监督管理委员会行政处罚委员会办公室备案。当事人如果对本处罚决定不服,可在收到本处罚决定书之日起60日内向中国证券监督管理委员会申请行政复议,也可在收到本处罚决定书之日起6个月内直接向有管辖权的人民法院提起行政诉讼。复议和诉讼期间,上述决定不停止执行。中国证监会2023年6月6日 | D3: 45083
