Workbook

Sheet Sheet1
A1: 文本序 | B1: 股票代码 | C1: 股票名称 | D1: 开始日期 | E1: 结束日期 | F1: 操纵期间 | G1: 处罚宣告日 | H1: 备注
A2: 202423 | B2: =VLOOKUP(C2,'[1]全部股票代码（手动检索）'!A:B,2,0) -> 002730.SZ | C2: 电光科技 | D2: 44180 | E2: 44517 | G2: 45352
A3: 202409 | B3: 400252.SZ | C3: 美尚生态 | D3: 43263 | E3: 44015 | G3: 45307
B4: =VLOOKUP(C4,[1]补充空白与2019的股票代码!A:B,2,0) -> 603518.SH | C4: 维格娜丝 | D4: 42941 | E4: 42961 | F4: 2017年7月25日至8月14日 | G4: 45306 | H4: 1支股票在两段时期内被操纵
B5: =VLOOKUP(C5,[1]补充空白与2019的股票代码!A:B,2,0) -> 603518.SH | C5: 维格娜丝 | D5: 42970 | E5: 42992 | F5: 2017年8月23日至9月14日 | G5: 45306
B6: =VLOOKUP(C6,[1]补充空白与2019的股票代码!A:B,2,0) -> 603665.SH | C6: 康隆达 | D6: 42998 | E6: 43007 | F6: 2017年9月20日至9月29日 | G6: 45306
B7: =VLOOKUP(C7,[1]补充空白与2019的股票代码!A:B,2,0) -> 603586.SH | C7: 金麒麟 | D7: 42969 | E7: 42978 | F7: 2017年8月22日至8月31日 | G7: 45306 | H7: 1支股票在两段时期内被操纵
B8: =VLOOKUP(C8,[1]补充空白与2019的股票代码!A:B,2,0) -> 603586.SH | C8: 金麒麟 | D8: 42982 | E8: 43000 | F8: 2017年9月4日至9月22日 | G8: 45306
B9: =VLOOKUP(C9,[1]补充空白与2019的股票代码!A:B,2,0) -> 603926.SH | C9: 铁流股份 | D9: 42962 | E9: 42972 | F9: 2017年8月15日至8月25日 | G9: 45306
B10: =VLOOKUP(C10,[1]补充空白与2019的股票代码!A:B,2,0) -> 603116.SH | C10: 红蜻蜓 | D10: 42940 | E10: 42949 | F10: 2017年7月24日至8月2日 | G10: 45306 | H10: 1支股票在两段时期内被操纵
B11: =VLOOKUP(C11,[1]补充空白与2019的股票代码!A:B,2,0) -> 603116.SH | C11: 红蜻蜓 | D11: 42978 | E11: 42986 | F11: 2017年8月31日至9月8日 | G11: 45306
B12: =VLOOKUP(C12,[1]补充空白与2019的股票代码!A:B,2,0) -> 603218.SH | C12: 日月股份 | D12: 42936 | E12: 42942 | F12: 2017年7月20日至7月26日 | G12: 45306
B13: =VLOOKUP(C13,[1]补充空白与2019的股票代码!A:B,2,0) -> 603877.SH | C13: 太平鸟 | D13: 42912 | E13: 42923 | F13: 2017年6月26日至7月7日 | G13: 45306 | H13: 1支股票在两段时期内被操纵
B14: =VLOOKUP(C14,[1]补充空白与2019的股票代码!A:B,2,0) -> 603877.SH | C14: 太平鸟 | D14: 42936 | E14: 42944 | F14: 2017年7月20日至7月28日 | G14: 45306
B15: =VLOOKUP(C15,[1]补充空白与2019的股票代码!A:B,2,0) -> 603758.SH | C15: 秦安股份 | D15: 43172 | E15: 43193 | F15: 2018年3月13日至4月3日 | G15: 45306
B16: =VLOOKUP(C16,[1]补充空白与2019的股票代码!A:B,2,0) -> 603159.SH | C16: 上海亚虹 | D16: 43168 | E16: 43175 | F16: 2018年3月9日至3月16日 | G16: 45306
B17: =VLOOKUP(C17,[1]补充空白与2019的股票代码!A:B,2,0) -> 603985.SH | C17: 恒润股份 | D17: 43192 | E17: 43215 | F17: 2018年4月2日至4月25日 | G17: 45306
B18: =VLOOKUP(C18,[1]补充空白与2019的股票代码!A:B,2,0) -> 603767.SH | C18: 中马传动 | D18: 43165 | E18: 43201 | F18: 2018年3月6日至4月11日 | G18: 45306
A19: 202402 | B19: =VLOOKUP(C19,'[1]全部股票代码（手动检索）'!A:B,2,0) -> 300289.SZ | C19: 利德曼 | D19: 42801 | E19: 42951 | G19: 45296
A20: 2023151 | B20: =VLOOKUP(C20,'[1]全部股票代码（手动检索）'!A:B,2,0) -> 603638.SH | C20: 艾迪精密 | D20: 43228 | E20: 44761 | G20: 45279
A21: 202383 | B21: 300400.SZ | C21: 劲拓股份 | D21: 43045 | E21: 43584 | F21: 2017年11月6日至2019年4月29日 | G21: 45260
A22: 202377 | B22: =VLOOKUP(C22,'[1]全部股票代码（手动检索）'!A:B,2,0) -> 002358.SZ | C22: 森源电气 | D22: 43166 | E22: 43523 | G22: 45230 | H22: 操纵行为分成三个阶段，开始日期与结束日期分别为操作行为最早开始时间和最晚结束时间
A23: 202370 | B23: 002721.SZ | C23: 金一文化 | D23: 43076 | E23: 43248 | F23: 2017年12月7日至2018年5月28日 | G23: 45222
B24: =VLOOKUP(C24,'[1]全部股票代码（手动检索）'!A:B,2,0) -> 002734.SZ | C24: 利民股份 | D24: 42345 | E24: 42489 | F24: 2015年12月7日至2016年4月29日 | G24: 45191
B25: =VLOOKUP(C25,'[1]全部股票代码（手动检索）'!A:B,2,0) -> 600328.SH | C25: 兰太实业 | D25: 42314 | E25: 42479 | F25: 2015年11月6日至2016年4月19日 | G25: 45191
B26: =VLOOKUP(C26,'[1]全部股票代码（手动检索）'!A:B,2,0) -> 603309.SH | C26: 维力医疗 | D26: 42341 | E26: 42489 | F26: 2015年12月3日至2016年4月29日 | G26: 45191
B27: =VLOOKUP(C27,'[1]全部股票代码（手动检索）'!A:B,2,0) -> 600560.SH | C27: 金自天正 | D27: 42332 | E27: 42537 | F27: 2015年11月24日至2016年6月16日 | G27: 45191
B28: =VLOOKUP(C28,'[1]全部股票代码（手动检索）'!A:B,2,0) -> 600310.SH | C28: 桂东电力 | D28: 42384 | E28: 42480 | F28: 2016年1月15日至4月20日 | G28: 45191
B29: =VLOOKUP(C29,'[1]全部股票代码（手动检索）'!A:B,2,0) -> 300309.SZ | C29: 吉艾科技 | D29: 42318 | E29: 42522 | F29: 2015年11月10日至2016年6月1日 | G29: 45191
B30: =VLOOKUP(C30,'[1]全部股票代码（手动检索）'!A:B,2,0) -> 000411.SZ | C30: 英特集团 | D30: 42396 | E30: 42544 | F30: 2016年1月27日至2016年6月23日 | G30: 45191
B31: =VLOOKUP(C31,'[1]全部股票代码（手动检索）'!A:B,2,0) -> 000702.SZ | C31: 正虹科技 | D31: 42180 | E31: 42562 | F31: 2015年6月25日至2016年7月11日 | G31: 45191
B32: =VLOOKUP(C32,'[1]全部股票代码（手动检索）'!A:B,2,0) -> 000691.SZ | C32: 亚太实业 | D32: 42236 | E32: 42325 | F32: 2015年8月20日至11月17日 | G32: 45191
B33: =VLOOKUP(C33,'[1]全部股票代码（手动检索）'!A:B,2,0) -> 300478.SZ | C33: 杭州高新 | D33: 42212 | E33: 42332 | F33: 2015年7月27日至11月24日 | G33: 45191
B34: =VLOOKUP(C34,'[1]全部股票代码（手动检索）'!A:B,2,0) -> 002072.SZ | C34: 凯瑞德 | D34: 42396 | E34: 42710 | F34: 2016年1月27日至12月6日 | G34: 45191
B35: =VLOOKUP(C35,'[1]全部股票代码（手动检索）'!A:B,2,0) -> 002509.SZ | C35: 天广消防 | D35: 42227 | E35: 42440 | F35: 2015年8月11日至2016年3月11日 | G35: 45191
... B39: =VLOOKUP(C39,'[1]全部股票代码（手动检索）'!A:B,2,0) -> 600165.SH | C39: 新日恒力 | D39: 42759 | E39: 42822 | F39: 2017年1月24日至3月28日 | G39: 45191
A40: 202364 | B40: =VLOOKUP(C40,'[1]全部股票代码（手动检索）'!A:B,2,0) -> 832966.NQ | C40: 道尔智控 | D40: 42984 | E40: 43112 | F40: 2017年9月6日至2018年1月12日 | G40: 45170
A41: 202360 | B41: =VLOOKUP(C41,'[1]全部股票代码（手动检索）'!A:B,2,0) -> 002858.SZ | C41: 力盛运动 | D41: 43833 | E41: 44189 | F41: 2020年1月3日至12月24日 | G41: 45154
A42: 202355 | B42: =VLOOKUP(C42,'[1]全部股票代码（手动检索）'!A:B,2,0) -> 002760.SZ | C42: 凤形股份 | D42: 43017 | E42: 43159 | F42: 2017年10月9日至2018年2月28日 | G42: 45121
A43: 202354 | B43: =VLOOKUP(C43,'[1]全部股票代码（手动检索）'!A:B,2,0) -> 000673.SZ | C43: 当代东方 | D43: 42970 | E43: 43327 | F43: 2017年8月23日至2018年8月15日 | G43: 45113
...
